Workbook

Sheet เริ่มที่นี่
A1: แม่แบบโครงการ TCRoof (ทุกกรณี), เริ่มที่นี่
A2: เลือกบทบาทของคุณด้านล่าง ทำแค่ 3 อย่างต่อสัปดาห์, ที่เหลือคำนวณเอง
A4: วันที่ข้อมูล | C4: COD ทั้งเฟส (คาดการณ์) | E4: ติดตั้งแล้ว | F4: COD แล้ว | G4: Milestone ทำได้ตามที่ควร | I4: ดึงจากแอปล่าสุด
A5: =ASOF -> 46328 | C5: ='Master Plan'!C4 -> 46433 | E5: ='Master Plan'!F4 -> 0 / 20 | F5: ='Master Plan'!D4 -> 0 / 20 | G5: =Milestone!G4 -> 0 | I5: =IF(ISNUMBER(TCRoof!B3),TCRoof!B3,"ยังไม่เชื่อม") -> ยังไม่เชื่อม
A7: Admin โครงการ | B7: 1. กรอกวันจริง / นัด / Y ที่ชีตอัปเดต (ช่องเหลือง) | H7: → อัปเดตรายสัปดาห์
B8: 2. แก้แถวที่มี ⚠ ใน Master Plan (คอลัมน์ขวาสุด) | H8: → Master Plan
B9: 3. นัดเลื่อน → บันทึก 1 แถว (เหตุผล + ผู้อนุมัติ) | H9: → บันทึกการเปลี่ยนแปลง
A11: วิศวกร | B11: 1. ดูงานของสัปดาห์นี้และ 3 สัปดาห์ข้างหน้า | H11: → งาน 3 สัปดาห์ข้างหน้า
B12: 2. กรอก S / Y ชิ้นงานของสัปดาห์ (กรองชื่อตัวเอง + ‘ช่วงนี้’), งานติดตั้งรายจุดที่ชีตจุดติดตั้ง | H12: → อัปเดตงาน WBS
B13: 3. ก่อนติ๊กเสร็จ ดูจุดตรวจ ICL ตามแบบมาตรฐาน, เจองานแก้ซ้ำ → บันทึกที่ Cost of Quality | H13: → ICL ตรวจหน้างาน
A15: ผู้รับเหมา | B15: 1. บันทึกงานในแอป TCRoof (รายงานประจำวัน, แผนงาน MP, IEC)
B16: 2. ดูแผนสถานีของตัวเองจากตารางด้านล่าง (กรอง ผรม.)
B17: ไม่ต้องกรอก Excel — ตัวเลขจากแอปเข้ามาเองทุก 5 นาที
A19: ผู้บริหาร / PM | B19: 1. ดูหมุดสำคัญ: ควรเสร็จ vs เสร็จจริง และ COD | H19: → Milestone
B20: 2. ดูความเสี่ยงระดับสูง และอนุมัติ CR ที่รออยู่ | H20: → ทะเบียนความเสี่ยง
B21: 3. ดูแนวโน้มรายสัปดาห์ | H21: → ประวัติสรุป
A24: หาสถานี: กรองคอลัมน์ ผรม. / วิศวกร แล้วคลิกรหัสเพื่อเปิดแผนของสถานีนั้น
A25: รหัส | B25: สถานี | C25: ผรม. | D25: วิศวกร | E25: COD คาดการณ์ | F25: ช้ากว่า Baseline (วัน) | G25: % งาน | H25: งานถัดไป | I25: ⚠ ตรวจข้อมูล
A26: P9-001 | B26: แม่แบบ หลังคาลอนคู่, กันย้อน HV, Inverter < 200 kVA | C26: 01 | D26: วศ.01 | E26: ='Master Plan'!$AH$8 -> 46433 | F26: ='Master Plan'!$AJ$8 -> -3 | G26: ='Master Plan'!$AM$8 -> 0 | H26: ='P9-001'!$B$5 -> จัดหาและรับอุปกรณ์ (หนังสือส่งแผง + ตรวจรับของ) | I26: ='Master Plan'!$AN$8
A27: P9-002 | B27: แม่แบบ หลังคาลอนคู่, กันย้อน HV, Inverter ≥ 200 kVA | C27: 02 | D27: วศ.02 | E27: ='Master Plan'!$AH$9 -> 46433 | F27: ='Master Plan'!$AJ$9 -> -3 | G27: ='Master Plan'!$AM$9 -> 0 | H27: ='P9-002'!$B$5 -> จัดหาและรับอุปกรณ์ (หนังสือส่งแผง + ตรวจรับของ) | I27: ='Master Plan'!$AN$9
A28: P9-003 | B28: แม่แบบ หลังคาลอนคู่, กันย้อน LV, Inverter < 200 kVA | C28: 03 | D28: วศ.03 | E28: ='Master Plan'!$AH$10 -> 46433 | F28: ='Master Plan'!$AJ$10 -> -3 | G28: ='Master Plan'!$AM$10 -> 0 | H28: ='P9-003'!$B$5 -> จัดหาและรับอุปกรณ์ (หนังสือส่งแผง + ตรวจรับของ) | I28: ='Master Plan'!$AN$10
A29: P9-004 | B29: แม่แบบ หลังคาลอนคู่, กันย้อน LV, Inverter ≥ 200 kVA | C29: 04 | D29: วศ.04 | E29: ='Master Plan'!$AH$11 -> 46433 | F29: ='Master Plan'!$AJ$11 -> -3 | G29: ='Master Plan'!$AM$11 -> 0 | H29: ='P9-004'!$B$5 -> จัดหาและรับอุปกรณ์ (หนังสือส่งแผง + ตรวจรับของ) | I29: ='Master Plan'!$AN$11
A30: P9-005 | B30: แม่แบบ หลังคาเมทัลชีท, กันย้อน HV, Inverter < 200 kVA | C30: 05 | D30: วศ.05 | E30: ='Master Plan'!$AH$12 -> 46433 | F30: ='Master Plan'!$AJ$12 -> -3 | G30: ='Master Plan'!$AM$12 -> 0 | H30: ='P9-005'!$B$5 -> จัดหาและรับอุปกรณ์ (หนังสือส่งแผง + ตรวจรับของ) | I30: ='Master Plan'!$AN$12
A31: P9-006 | B31: แม่แบบ หลังคาเมทัลชีท, กันย้อน HV, Inverter ≥ 200 kVA | C31: 06 | D31: วศ.06 | E31: ='Master Plan'!$AH$13 -> 46433 | F31: ='Master Plan'!$AJ$13 -> -3 | G31: ='Master Plan'!$AM$13 -> 0 | H31: ='P9-006'!$B$5 -> จัดหาและรับอุปกรณ์ (หนังสือส่งแผง + ตรวจรับของ) | I31: ='Master Plan'!$AN$13
A32: P9-007 | B32: แม่แบบ หลังคาเมทัลชีท, กันย้อน LV, Inverter < 200 kVA | C32: 07 | D32: วศ.07 | E32: ='Master Plan'!$AH$14 -> 46433 | F32: ='Master Plan'!$AJ$14 -> -3 | G32: ='Master Plan'!$AM$14 -> 0 | H32: ='P9-007'!$B$5 -> จัดหาและรับอุปกรณ์ (หนังสือส่งแผง + ตรวจรับของ) | I32: ='Master Plan'!$AN$14
A33: P9-008 | B33: แม่แบบ หลังคาเมทัลชีท, กันย้อน LV, Inverter ≥ 200 kVA | C33: 08 | D33: วศ.08 | E33: ='Master Plan'!$AH$15 -> 46433 | F33: ='Master Plan'!$AJ$15 -> -3 | G33: ='Master Plan'!$AM$15 -> 0 | H33: ='P9-008'!$B$5 -> จัดหาและรับอุปกรณ์ (หนังสือส่งแผง + ตรวจรับของ) | I33: ='Master Plan'!$AN$15
A34: P9-009 | B34: แม่แบบ ถังน้ำใส, กันย้อน HV, Inverter < 200 kVA | C34: 09 | D34: วศ.09 | E34: ='Master Plan'!$AH$16 -> 46433 | F34: ='Master Plan'!$AJ$16 -> -3 | G34: ='Master Plan'!$AM$16 -> 0 | H34: ='P9-009'!$B$5 -> จัดหาและรับอุปกรณ์ (หนังสือส่งแผง + ตรวจรับของ) | I34: ='Master Plan'!$AN$16
A35: P9-010 | B35: แม่แบบ ถังน้ำใส, กันย้อน HV, Inverter ≥ 200 kVA | C35: 10 | D35: วศ.10 | E35: ='Master Plan'!$AH$17 -> 46433 | F35: ='Master Plan'!$AJ$17 -> -3 | G35: ='Master Plan'!$AM$17 -> 0 | H35: ='P9-010'!$B$5 -> จัดหาและรับอุปกรณ์ (หนังสือส่งแผง + ตรวจรับของ) | I35: ='Master Plan'!$AN$17
A36: P9-011 | B36: แม่แบบ ถังน้ำใส, กันย้อน LV, Inverter < 200 kVA | C36: 11 | D36: วศ.11 | E36: ='Master Plan'!$AH$18 -> 46433 | F36: ='Master Plan'!$AJ$18 -> -3 | G36: ='Master Plan'!$AM$18 -> 0 | H36: ='P9-011'!$B$5 -> จัดหาและรับอุปกรณ์ (หนังสือส่งแผง + ตรวจรับของ) | I36: ='Master Plan'!$AN$18
A37: P9-012 | B37: แม่แบบ ถังน้ำใส, กันย้อน LV, Inverter ≥ 200 kVA | C37: 12 | D37: วศ.12 | E37: ='Master Plan'!$AH$19 -> 46433 | F37: ='Master Plan'!$AJ$19 -> -3 | G37: ='Master Plan'!$AM$19 -> 0 | H37: ='P9-012'!$B$5 -> จัดหาและรับอุปกรณ์ (หนังสือส่งแผง + ตรวจรับของ) | I37: ='Master Plan'!$AN$19
A38: P9-013 | B38: แม่แบบ ถังดินกลบ, กันย้อน HV, Inverter < 200 kVA | C38: 13 | D38: วศ.13 | E38: ='Master Plan'!$AH$20 -> 46433 | F38: ='Master Plan'!$AJ$20 -> -3 | G38: ='Master Plan'!$AM$20 -> 0 | H38: ='P9-013'!$B$5 -> จัดหาและรับอุปกรณ์ (หนังสือส่งแผง + ตรวจรับของ) | I38: ='Master Plan'!$AN$20
A39: P9-014 | B39: แม่แบบ ถังดินกลบ, กันย้อน HV, Inverter ≥ 200 kVA | C39: 14 | D39: วศ.14 | E39: ='Master Plan'!$AH$21 -> 46433 | F39: ='Master Plan'!$AJ$21 -> -3 | G39: ='Master Plan'!$AM$21 -> 0 | H39: ='P9-014'!$B$5 -> จัดหาและรับอุปกรณ์ (หนังสือส่งแผง + ตรวจรับของ) | I39: ='Master Plan'!$AN$21
A40: P9-015 | B40: แม่แบบ ถังดินกลบ, กันย้อน LV, Inverter < 200 kVA | C40: 15 | D40: วศ.15 | E40: ='Master Plan'!$AH$22 -> 46433 | F40: ='Master Plan'!$AJ$22 -> -3 | G40: ='Master Plan'!$AM$22 -> 0 | H40: ='P9-015'!$B$5 -> จัดหาและรับอุปกรณ์ (หนังสือส่งแผง + ตรวจรับของ) | I40: ='Master Plan'!$AN$22
A41: P9-016 | B41: แม่แบบ ถังดินกลบ, กันย้อน LV, Inverter ≥ 200 kVA | C41: 16 | D41: วศ.16 | E41: ='Master Plan'!$AH$23 -> 46433 | F41: ='Master Plan'!$AJ$23 -> -3 | G41: ='Master Plan'!$AM$23 -> 0 | H41: ='P9-016'!$B$5 -> จัดหาและรับอุปกรณ์ (หนังสือส่งแผง + ตรวจรับของ) | I41: ='Master Plan'!$AN$23
A42: P9-017 | B42: แม่แบบ Carport, กันย้อน HV, Inverter < 200 kVA | C42: 17 | D42: วศ.17 | E42: ='Master Plan'!$AH$24 -> 46433 | F42: ='Master Plan'!$AJ$24 -> -3 | G42: ='Master Plan'!$AM$24 -> 0 | H42: ='P9-017'!$B$5 -> จัดหาและรับอุปกรณ์ (หนังสือส่งแผง + ตรวจรับของ) | I42: ='Master Plan'!$AN$24
A43: P9-018 | B43: แม่แบบ Carport, กันย้อน HV, Inverter ≥ 200 kVA | C43: 18 | D43: วศ.18 | E43: ='Master Plan'!$AH$25 -> 46433 | F43: ='Master Plan'!$AJ$25 -> -3 | G43: ='Master Plan'!$AM$25 -> 0 | H43: ='P9-018'!$B$5 -> จัดหาและรับอุปกรณ์ (หนังสือส่งแผง + ตรวจรับของ) | I43: ='Master Plan'!$AN$25
A44: P9-019 | B44: แม่แบบ Carport, กันย้อน LV, Inverter < 200 kVA | C44: 19 | D44: วศ.19 | E44: ='Master Plan'!$AH$26 -> 46433 | F44: ='Master Plan'!$AJ$26 -> -3 | G44: ='Master Plan'!$AM$26 -> 0 | H44: ='P9-019'!$B$5 -> จัดหาและรับอุปกรณ์ (หนังสือส่งแผง + ตรวจรับของ) | I44: ='Master Plan'!$AN$26
A45: P9-020 | B45: แม่แบบ Carport, กันย้อน LV, Inverter ≥ 200 kVA | C45: 20 | D45: วศ.20 | E45: ='Master Plan'!$AH$27 -> 46433 | F45: ='Master Plan'!$AJ$27 -> -3 | G45: ='Master Plan'!$AM$27 -> 0 | H45: ='P9-020'!$B$5 -> จัดหาและรับอุปกรณ์ (หนังสือส่งแผง + ตรวจรับของ) | I45: ='Master Plan'!$AN$27

Sheet อัปเดตรายสัปดาห์
A1: อัปเดตความคืบหน้ารายสัปดาห์ – กรอกที่นี่ที่เดียว
A2: ช่องเหลือง: ใส่ ‘วันที่’ (วันเสร็จจริง หรือวันนัดถ้ายังไม่ถึง) หรือ ‘Y’ = เสร็จแล้วแต่ไม่รู้วันที่, ปีเป็น ค.ศ. 2026–2027 เท่านั้น (ระบบไม่รับปี พ.ศ.), ส้ม = วันนัด (หลังวันที่ข้อมูล), เทา = ไม่ต้องทำ, Master Plan และแผนรายโครงการอัปเดตทันที
A3: วันที่ข้อมูล: | B3: =ASOF -> 46328 | C3: ⚙ เปลี่ยนวันที่ข้อมูลที่ชีตสมมติฐาน
A6: สถานี | G6: Part 0 จัดหาและเตรียมงาน (น้ำหนัก 0) | J6: Part PERMIT | W6: Part ติดตั้งอุปกรณ์ | AG6: Part การทดสอบ ส่งมอบ และ PAC
A7: รหัส | B7: สถานี | C7: เขต กฟภ. | D7: Admin | E7: วิศวกร | F7: รอบ | G7: 0.1 บริหาร/HSE/QA | H7: 0.2 รับแผง/อุปกรณ์ | I7: 0.3 หนังสือขอดับไฟ | J7: 1.1 Kick Off | K7: 1.2 Eng. Approve | L7: 1.3 ส่งมอบพื้นที่ | M7: 1.4 อ.1 / เทศบาล | N7: 1.5 ยื่น พค.2 | O7: 1.5.3 พพ. ความเห็น | P7: 1.6 COP / แจ้ง กกพ. | Q7: 1.7.1 ยื่น PPIM | R7: 1.7.2 ยื่นแก้ไขล่าสุด | S7: 1.7.3 ผลพิจารณาแบบ | T7: 1.7.4 ชำระค่าธรรมเนียม | U7: 1.7.5 ขอตรวจระบบ | V7: 1.7.6 ขนานไฟ COD | W7: 2.1 โครงสร้าง+Walkway | X7: 2.2 DC | Y7: 2.3 แผง | Z7: 2.4 FTS | AA7: 2.5 Inverter | AB7: 2.6 AC / MV | AC7: 2.7 ตู้ควบคุม | AD7: 2.8 สื่อสาร+ZE | AE7: 2.9 Monitoring (ติดตั้ง) | AF7: 2.10 ดับไฟเชื่อมระบบ | AG7: 3.1 IEC 62446 | AH7: 3.1.7 ตรวจรับ กฟภ. | AI7: 3.1.2 As-built ส่ง ผรม. | AJ7: 3.1.8 As-built ลงนาม | AK7: 3.2 อบรม/PAC | AL7: 3.2.4 ส่งมอบงวด | AM7: 3.2.5 C-Form ข. | AN7: 3.2.6 C-Form ก. | AO7: 3.2.7 Monitoring ออนระบบ | AP7: หมายเหตุสัปดาห์นี้
A8: P9-001 | B8: แม่แบบ หลังคาลอนคู่, กันย้อน HV, Inverter < 200 kVA | C8: ตย.01 | D8: Admin | E8: วศ.01 | F8: รอบ 9
A9: P9-002 | B9: แม่แบบ หลังคาลอนคู่, กันย้อน HV, Inverter ≥ 200 kVA | C9: ตย.02 | D9: Admin | E9: วศ.02 | F9: รอบ 9
A10: P9-003 | B10: แม่แบบ หลังคาลอนคู่, กันย้อน LV, Inverter < 200 kVA | C10: ตย.03 | D10: Admin | E10: วศ.03 | F10: รอบ 9
A11: P9-004 | B11: แม่แบบ หลังคาลอนคู่, กันย้อน LV, Inverter ≥ 200 kVA | C11: ตย.04 | D11: Admin | E11: วศ.04 | F11: รอบ 9
A12: P9-005 | B12: แม่แบบ หลังคาเมทัลชีท, กันย้อน HV, Inverter < 200 kVA | C12: ตย.05 | D12: Admin | E12: วศ.05 | F12: รอบ 9
A13: P9-006 | B13: แม่แบบ หลังคาเมทัลชีท, กันย้อน HV, Inverter ≥ 200 kVA | C13: ตย.06 | D13: Admin | E13: วศ.06 | F13: รอบ 9
A14: P9-007 | B14: แม่แบบ หลังคาเมทัลชีท, กันย้อน LV, Inverter < 200 kVA | C14: ตย.07 | D14: Admin | E14: วศ.07 | F14: รอบ 9
A15: P9-008 | B15: แม่แบบ หลังคาเมทัลชีท, กันย้อน LV, Inverter ≥ 200 kVA | C15: ตย.08 | D15: Admin | E15: วศ.08 | F15: รอบ 9
A16: P9-009 | B16: แม่แบบ ถังน้ำใส, กันย้อน HV, Inverter < 200 kVA | C16: ตย.09 | D16: Admin | E16: วศ.09 | F16: รอบ 9
A17: P9-010 | B17: แม่แบบ ถังน้ำใส, กันย้อน HV, Inverter ≥ 200 kVA | C17: ตย.10 | D17: Admin | E17: วศ.10 | F17: รอบ 9
A18: P9-011 | B18: แม่แบบ ถังน้ำใส, กันย้อน LV, Inverter < 200 kVA | C18: ตย.11 | D18: Admin | E18: วศ.11 | F18: รอบ 9
A19: P9-012 | B19: แม่แบบ ถังน้ำใส, กันย้อน LV, Inverter ≥ 200 kVA | C19: ตย.12 | D19: Admin | E19: วศ.12 | F19: รอบ 9
... A27: P9-020 | B27: แม่แบบ Carport, กันย้อน LV, Inverter ≥ 200 kVA | C27: ตย.20 | D27: Admin | E27: วศ.20 | F27: รอบ 9

Sheet อัปเดตงาน WBS
A1: อัปเดตงาน WBS รายสัปดาห์ – ทุกสถานีในหน้าเดียว
A2: สัปดาห์ละครั้ง: กรองคอลัมน์ ‘วิศวกร’ เป็นชื่อตัวเอง และ ‘ช่วงนี้’ → กรอกสถานะ S = เริ่มแล้ว (นับ 50% เฉพาะงาน 50/50), Y = ครบตามเกณฑ์เสร็จ ทำหลายงานพร้อมกันได้ กรอก S หลายแถวได้, ดูจากรายงานประจำวัน (R2) และรูปในแอป TCRoof, ICL ไม่ผ่าน → ลด Y เป็น S แล้วบันทึก Cost of Quality
A3: ไม่ต้องกรอกที่นี่: หมุด ◆ (ใส่วันที่ในชีตอัปเดตรายสัปดาห์), โครงสร้าง / DC / แผงของสถานีที่ระบุจุดติดตั้งแล้ว (ติ๊กรายจุดในชีตจุดติดตั้ง), ขั้นงาน Inverter station (ชีตสถานี), งานที่ไม่เป็นชิ้นงาน เช่น ขนของ รอวัสดุ (ลงใน R2 อย่างเดียว)
A4: ช่วงนี้ (ยังไม่เสร็จ) | C4: เลยกำหนด | E4: เริ่มแล้ว (S) | G4: เสร็จ (Y)
A5: =COUNTIF($K$7:$K$1646,"ช่วงนี้") -> 770 | C5: =COUNTIF($K$7:$K$1646,"⚠*") -> 0 | E5: =COUNTIF($L$7:$L$1646,"S") -> 0 | G5: =COUNTIF($L$7:$L$1646,"Y") -> 0
A6: รหัส | B6: สถานี | C6: วิศวกร | D6: ผรม. | E6: WBS | F6: ชิ้นงาน | G6: เกณฑ์เสร็จ (ต้องมีหลักฐาน) | H6: วิธีนับ | I6: เริ่ม (คาดการณ์) | J6: เสร็จ (คาดการณ์) | K6: ช่วงนี้ | L6: สถานะ (S / Y) | M6: หลักฐาน / หมายเหตุ
A7: P9-001 | B7: แม่แบบ หลังคาลอนคู่, กันย้อน HV, Inverter < 200 kVA | C7: วศ.01 | D7: 01 | E7: 0.1.1 | F7: แผนบริหารโครงการ (PEP) + Baseline | G7: ผู้ว่าจ้างอนุมัติ Baseline ก่อนเริ่มรายงาน S-Curve | H7: 0/100 | I7: ='P9-001'!$N$10 -> 46328 | J7: ='P9-001'!$O$10 -> 46340 | K7: =IF(OR(L7="Y",LEFT('P9-001'!$T$10,1)="D"),"",IF(AND(ISNUMBER(J7),J7<ASOF),"⚠ เลยกำหนด",IF(AND(ISNUMBER(I7),I7<=ASOF+14,J7>=ASOF-7),"ช่วงนี้",""))) -> ช่วงนี้
A8: P9-001 | B8: แม่แบบ หลังคาลอนคู่, กันย้อน HV, Inverter < 200 kVA | C8: วศ.01 | D8: 01 | E8: 0.1.2 | F8: แผนความปลอดภัย (HSE Plan, JSA, Permit-to-Work) | G8: แผน HSE อนุมัติก่อนเข้าพื้นที่ | H8: 0/100 | I8: ='P9-001'!$N$11 -> 46328 | J8: ='P9-001'!$O$11 -> 46340 | K8: =IF(OR(L8="Y",LEFT('P9-001'!$T$11,1)="D"),"",IF(AND(ISNUMBER(J8),J8<ASOF),"⚠ เลยกำหนด",IF(AND(ISNUMBER(I8),I8<=ASOF+14,J8>=ASOF-7),"ช่วงนี้",""))) -> ช่วงนี้
A9: P9-001 | B9: แม่แบบ หลังคาลอนคู่, กันย้อน HV, Inverter < 200 kVA | C9: วศ.01 | D9: 01 | E9: 0.1.3 | F9: แผนคุณภาพ (PQP) + แผนตรวจทดสอบ (ITP) | G9: ITP อนุมัติ ใช้เป็นเกณฑ์ตรวจรับทุกงาน | H9: 0/100 | I9: ='P9-001'!$N$12 -> 46328 | J9: ='P9-001'!$O$12 -> 46340 | K9: =IF(OR(L9="Y",LEFT('P9-001'!$T$12,1)="D"),"",IF(AND(ISNUMBER(J9),J9<ASOF),"⚠ เลยกำหนด",IF(AND(ISNUMBER(I9),I9<=ASOF+14,J9>=ASOF-7),"ช่วงนี้",""))) -> ช่วงนี้
A10: P9-001 | B10: แม่แบบ หลังคาลอนคู่, กันย้อน HV, Inverter < 200 kVA | C10: วศ.01 | D10: 01 | E10: 0.1.4 | F10: เอกสารขออนุมัติวัสดุ (Material submittal) | G10: เอกสารอนุมัติวัสดุครบก่อนส่งของ | H10: 0/100 | I10: ='P9-001'!$N$13 -> 46328 | J10: ='P9-001'!$O$13 -> 46346 | K10: =IF(OR(L10="Y",LEFT('P9-001'!$T$13,1)="D"),"",IF(AND(ISNUMBER(J10),J10<ASOF),"⚠ เลยกำหนด",IF(AND(ISNUMBER(I10),I10<=ASOF+14,J10>=ASOF-7),"ช่วงนี้",""))) -> ช่วงนี้
A11: P9-001 | B11: แม่แบบ หลังคาลอนคู่, กันย้อน HV, Inverter < 200 kVA | C11: วศ.01 | D11: 01 | E11: 0.1.5 | F11: รายงานประจำ R1–R4 | G11: ส่งตรงเวลาทุกงวด, R2 ลงนามรับทราบโดยวิศวกร | H11: 0/100 | I11: ='P9-001'!$N$14 -> 46340 | J11: ='P9-001'!$O$14 -> 46450 | K11: =IF(OR(L11="Y",LEFT('P9-001'!$T$14,1)="D"),"",IF(AND(ISNUMBER(J11),J11<ASOF),"⚠ เลยกำหนด",IF(AND(ISNUMBER(I11),I11<=ASOF+14,J11>=ASOF-7),"ช่วงนี้",""))) -> ช่วงนี้
A12: P9-001 | B12: แม่แบบ หลังคาลอนคู่, กันย้อน HV, Inverter < 200 kVA | C12: วศ.01 | D12: 01 | E12: 0.1.6 | F12: การตรวจ HSE / NCR / Punch list หน้างาน | G12: NCR และ Punch list ปิดครบก่อน PAC | H12: 0/100 | I12: ='P9-001'!$N$15 -> 46340 | J12: ='P9-001'!$O$15 -> 46450 | K12: =IF(OR(L12="Y",LEFT('P9-001'!$T$15,1)="D"),"",IF(AND(ISNUMBER(J12),J12<ASOF),"⚠ เลยกำหนด",IF(AND(ISNUMBER(I12),I12<=ASOF+14,J12>=ASOF-7),"ช่วงนี้",""))) -> ช่วงนี้
A13: P9-001 | B13: แม่แบบ หลังคาลอนคู่, กันย้อน HV, Inverter < 200 kVA | C13: วศ.01 | D13: 01 | E13: 0.2.1 | F13: หนังสือส่งแผง / ใบเบิกจากคลัง | G13: มีเลขที่หนังสือ (TC-PML-…) | H13: 0/100 | I13: ='P9-001'!$N$17 -> 46328 | J13: ='P9-001'!$O$17 -> 46328 | K13: =IF(OR(L13="Y",LEFT('P9-001'!$T$17,1)="D"),"",IF(AND(ISNUMBER(J13),J13<ASOF),"⚠ เลยกำหนด",IF(AND(ISNUMBER(I13),I13<=ASOF+14,J13>=ASOF-7),"ช่วงนี้",""))) -> ช่วงนี้
A14: P9-001 | B14: แม่แบบ หลังคาลอนคู่, กันย้อน HV, Inverter < 200 kVA | C14: วศ.01 | D14: 01 | E14: 0.2.2 | F14: ผล FAT Inverter / ตู้ไฟ (+ CT/VT 22 kV) | G14: ใบรับรอง/ผล FAT แนบในเอกสารสถานี | H14: 0/100 | I14: ='P9-001'!$N$18 -> 46328 | J14: ='P9-001'!$O$18 -> 46328 | K14: =IF(OR(L14="Y",LEFT('P9-001'!$T$18,1)="D"),"",IF(AND(ISNUMBER(J14),J14<ASOF),"⚠ เลยกำหนด",IF(AND(ISNUMBER(I14),I14<=ASOF+14,J14>=ASOF-7),"ช่วงนี้",""))) -> ช่วงนี้
A15: P9-001 | B15: แม่แบบ หลังคาลอนคู่, กันย้อน HV, Inverter < 200 kVA | C15: วศ.01 | D15: 01 | E15: 0.2.3 | F15: แผง + Inverter ถึงหน้างาน (ตรวจรับ + S/N) | G15: จำนวนตรง BOM, ไม่มีชำรุด, S/N เข้าแอป | H15: 0/100 | I15: ='P9-001'!$N$19 -> 46328 | J15: ='P9-001'!$O$19 -> 46328 | K15: =IF(OR(L15="Y",LEFT('P9-001'!$T$19,1)="D"),"",IF(AND(ISNUMBER(J15),J15<ASOF),"⚠ เลยกำหนด",IF(AND(ISNUMBER(I15),I15<=ASOF+14,J15>=ASOF-7),"ช่วงนี้",""))) -> ช่วงนี้
A16: P9-001 | B16: แม่แบบ หลังคาลอนคู่, กันย้อน HV, Inverter < 200 kVA | C16: วศ.01 | D16: 01 | E16: 0.2.4 | F16: โครงยึด + Walkway ถึงหน้างาน | G16: ตรวจรับตาม shop drawing | H16: 0/100 | I16: ='P9-001'!$N$20 -> 46328 | J16: ='P9-001'!$O$20 -> 46328 | K16: =IF(OR(L16="Y",LEFT('P9-001'!$T$20,1)="D"),"",IF(AND(ISNUMBER(J16),J16<ASOF),"⚠ เลยกำหนด",IF(AND(ISNUMBER(I16),I16<=ASOF+14,J16>=ASOF-7),"ช่วงนี้",""))) -> ช่วงนี้
A17: P9-001 | B17: แม่แบบ หลังคาลอนคู่, กันย้อน HV, Inverter < 200 kVA | C17: วศ.01 | D17: 01 | E17: 0.2.5 | F17: สายไฟ + รางสาย ถึงหน้างาน | G17: ตรวจรับขนาด/ยี่ห้อตาม submittal | H17: 0/100 | I17: ='P9-001'!$N$21 -> 46328 | J17: ='P9-001'!$O$21 -> 46328 | K17: =IF(OR(L17="Y",LEFT('P9-001'!$T$21,1)="D"),"",IF(AND(ISNUMBER(J17),J17<ASOF),"⚠ เลยกำหนด",IF(AND(ISNUMBER(I17),I17<=ASOF+14,J17>=ASOF-7),"ช่วงนี้",""))) -> ช่วงนี้
A18: P9-001 | B18: แม่แบบ หลังคาลอนคู่, กันย้อน HV, Inverter < 200 kVA | C18: วศ.01 | D18: 01 | E18: 0.2.6 | F18: ตู้ไฟ FTS / DC / AC / METER / PQM / SEM ถึงหน้างาน | G18: ตรวจรับภายในตู้ตามแบบ SLD | H18: 0/100 | I18: ='P9-001'!$N$22 -> 46328 | J18: ='P9-001'!$O$22 -> 46328 | K18: =IF(OR(L18="Y",LEFT('P9-001'!$T$22,1)="D"),"",IF(AND(ISNUMBER(J18),J18<ASOF),"⚠ เลยกำหนด",IF(AND(ISNUMBER(I18),I18<=ASOF+14,J18>=ASOF-7),"ช่วงนี้",""))) -> ช่วงนี้
A19: P9-001 | B19: แม่แบบ หลังคาลอนคู่, กันย้อน HV, Inverter < 200 kVA | C19: วศ.01 | D19: 01 | E19: 0.2.7 | F19: อุปกรณ์ 22 kV ถึงหน้างาน (VT / CT ผ่านทดสอบ กฟภ.) | G19: มีผลทดสอบ CT/VT | H19: 0/100 | I19: ='P9-001'!$N$23 -> 46328 | J19: ='P9-001'!$O$23 -> 46328 | K19: =IF(OR(L19="Y",LEFT('P9-001'!$T$23,1)="D"),"",IF(AND(ISNUMBER(J19),J19<ASOF),"⚠ เลยกำหนด",IF(AND(ISNUMBER(I19),I19<=ASOF+14,J19>=ASOF-7),"ช่วงนี้",""))) -> ช่วงนี้
A20: P9-001 | B20: แม่แบบ หลังคาลอนคู่, กันย้อน HV, Inverter < 200 kVA | C20: วศ.01 | D20: 01 | E20: 0.2.8 | F20: มิเตอร์ + อุปกรณ์สื่อสาร ถึงหน้างาน | G20: ตรวจรับรุ่นตามแบบ | H20: 0/100 | I20: ='P9-001'!$N$24 -> 46328 | J20: ='P9-001'!$O$24 -> 46328 | K20: =IF(OR(L20="Y",LEFT('P9-001'!$T$24,1)="D"),"",IF(AND(ISNUMBER(J20),J20<ASOF),"⚠ เลยกำหนด",IF(AND(ISNUMBER(I20),I20<=ASOF+14,J20>=ASOF-7),"ช่วงนี้",""))) -> ช่วงนี้
A21: P9-001 | B21: แม่แบบ หลังคาลอนคู่, กันย้อน HV, Inverter < 200 kVA | C21: วศ.01 | D21: 01 | E21: 0.3.1 | F21: ร่างหนังสือแจ้งดับไฟ | G21: ร่างหนังสือ + ช่วงดับไฟที่ไม่กระทบการสูบจ่ายน้ำ (สาขายืนยัน) | H21: 0/100 | I21: ='P9-001'!$N$26 -> 46329 | J21: ='P9-001'!$O$26 -> 46329 | K21: =IF(OR(L21="Y",LEFT('P9-001'!$T$26,1)="D"),"",IF(AND(ISNUMBER(J21),J21<ASOF),"⚠ เลยกำหนด",IF(AND(ISNUMBER(I21),I21<=ASOF+14,J21>=ASOF-7),"ช่วงนี้",""))) -> ช่วงนี้
A22: P9-001 | B22: แม่แบบ หลังคาลอนคู่, กันย้อน HV, Inverter < 200 kVA | C22: วศ.01 | D22: 01 | E22: 0.3.2 | F22: หนังสือแจ้งดับไฟ (ส่งล่วงหน้า ≥ 7 วัน) | G22: เลขที่ TC-PML-… และวันส่ง | H22: 0/100 | I22: ='P9-001'!$N$27 -> 46329 | J22: ='P9-001'!$O$27 -> 46329 | K22: =IF(OR(L22="Y",LEFT('P9-001'!$T$27,1)="D"),"",IF(AND(ISNUMBER(J22),J22<ASOF),"⚠ เลยกำหนด",IF(AND(ISNUMBER(I22),I22<=ASOF+14,J22>=ASOF-7),"ช่วงนี้",""))) -> ช่วงนี้
A23: P9-001 | B23: แม่แบบ หลังคาลอนคู่, กันย้อน HV, Inverter < 200 kVA | C23: วศ.01 | D23: 01 | E23: 0.3.3 | F23: วันดับไฟที่ยืนยันแล้ว (สาขา / กฟภ.) | G23: วันดับไฟยืนยันเป็นลายลักษณ์อักษร (สาขา + กฟภ. ถ้า HV) | H23: 0/100 | I23: ='P9-001'!$N$28 -> 46329 | J23: ='P9-001'!$O$28 -> 46329 | K23: =IF(OR(L23="Y",LEFT('P9-001'!$T$28,1)="D"),"",IF(AND(ISNUMBER(J23),J23<ASOF),"⚠ เลยกำหนด",IF(AND(ISNUMBER(I23),I23<=ASOF+14,J23>=ASOF-7),"ช่วงนี้",""))) -> ช่วงนี้
A24: P9-001 | B24: แม่แบบ หลังคาลอนคู่, กันย้อน HV, Inverter < 200 kVA | C24: วศ.01 | D24: 01 | E24: 1.1.1 | F24: บันทึกประชุม Kick off | G24: บันทึกการประชุม (MOM) ลงนามผู้เข้าร่วม | H24: 0/100 | I24: ='P9-001'!$N$31 -> 46328 | J24: ='P9-001'!$O$31 -> 46328 | K24: =IF(OR(L24="Y",LEFT('P9-001'!$T$31,1)="D"),"",IF(AND(ISNUMBER(J24),J24<ASOF),"⚠ เลยกำหนด",IF(AND(ISNUMBER(I24),I24<=ASOF+14,J24>=ASOF-7),"ช่วงนี้",""))) -> ช่วงนี้
A25: P9-001 | B25: แม่แบบ หลังคาลอนคู่, กันย้อน HV, Inverter < 200 kVA | C25: วศ.01 | D25: 01 | E25: 1.1.2 | F25: งาน PWA ในแอป TCRoof | G25: งานในแอปครบ: งาน PWA, เลข MP, ขนาด Inverter, ผู้รับเหมา, ทีม | H25: 0/100 | I25: ='P9-001'!$N$32 -> 46328 | J25: ='P9-001'!$O$32 -> 46328 | K25: =IF(OR(L25="Y",LEFT('P9-001'!$T$32,1)="D"),"",IF(AND(ISNUMBER(J25),J25<ASOF),"⚠ เลยกำหนด",IF(AND(ISNUMBER(I25),I25<=ASOF+14,J25>=ASOF-7),"ช่วงนี้",""))) -> ช่วงนี้
A26: P9-001 | B26: แม่แบบ หลังคาลอนคู่, กันย้อน HV, Inverter < 200 kVA | C26: วศ.01 | D26: 01 | E26: 1.1.3 | F26: แบบสำรวจหน้างาน A1–E1 (REV 00) | G26: แบบสำรวจ A1–E1 ลงนาม 2 ฝ่าย ออก REV 00 | H26: 0/100 | I26: ='P9-001'!$N$33 -> 46328 | J26: ='P9-001'!$O$33 -> 46328 | K26: =IF(OR(L26="Y",LEFT('P9-001'!$T$33,1)="D"),"",IF(AND(ISNUMBER(J26),J26<ASOF),"⚠ เลยกำหนด",IF(AND(ISNUMBER(I26),I26<=ASOF+14,J26>=ASOF-7),"ช่วงนี้",""))) -> ช่วงนี้
A27: P9-001 | B27: แม่แบบ หลังคาลอนคู่, กันย้อน HV, Inverter < 200 kVA | C27: วศ.01 | D27: 01 | E27: 1.2.1 | F27: SLD + Layout + String sizing | G27: SLD + Layout + String sizing ลงนามวิศวกร | H27: 0/100 | I27: ='P9-001'!$N$35 -> 46328 | J27: ='P9-001'!$O$35 -> 46328 | K27: =IF(OR(L27="Y",LEFT('P9-001'!$T$35,1)="D"),"",IF(AND(ISNUMBER(J27),J27<ASOF),"⚠ เลยกำหนด",IF(AND(ISNUMBER(I27),I27<=ASOF+14,J27>=ASOF-7),"ช่วงนี้",""))) -> ช่วงนี้
A28: P9-001 | B28: แม่แบบ หลังคาลอนคู่, กันย้อน HV, Inverter < 200 kVA | C28: วศ.01 | D28: 01 | E28: 1.2.2 | F28: รายการคำนวณไฟฟ้า / โครงสร้าง | G28: รายการคำนวณไฟฟ้า / โยธาลงนาม (มีผลน้ำหนักบนหลังคา) | H28: 0/100 | I28: ='P9-001'!$N$36 -> 46328 | J28: ='P9-001'!$O$36 -> 46328 | K28: =IF(OR(L28="Y",LEFT('P9-001'!$T$36,1)="D"),"",IF(AND(ISNUMBER(J28),J28<ASOF),"⚠ เลยกำหนด",IF(AND(ISNUMBER(I28),I28<=ASOF+14,J28>=ASOF-7),"ช่วงนี้",""))) -> ช่วงนี้
A29: P9-001 | B29: แม่แบบ หลังคาลอนคู่, กันย้อน HV, Inverter < 200 kVA | C29: วศ.01 | D29: 01 | E29: 1.2.3 | F29: ค่าตั้ง Protection / Zero export | G29: ตารางค่าตั้ง Protection / Zero export ลงนาม | H29: 0/100 | I29: ='P9-001'!$N$37 -> 46328 | J29: ='P9-001'!$O$37 -> 46328 | K29: =IF(OR(L29="Y",LEFT('P9-001'!$T$37,1)="D"),"",IF(AND(ISNUMBER(J29),J29<ASOF),"⚠ เลยกำหนด",IF(AND(ISNUMBER(I29),I29<=ASOF+14,J29>=ASOF-7),"ช่วงนี้",""))) -> ช่วงนี้
A30: P9-001 | B30: แม่แบบ หลังคาลอนคู่, กันย้อน HV, Inverter < 200 kVA | C30: วศ.01 | D30: 01 | E30: 1.2.4 | F30: แบบที่ กปภ. อนุมัติ (REV ล่าสุด) | G30: หนังสืออนุมัติแบบจาก กปภ. (REV ล่าสุด) | H30: 0/100 | I30: ='P9-001'!$N$38 -> 46328 | J30: ='P9-001'!$O$38 -> 46328 | K30: =IF(OR(L30="Y",LEFT('P9-001'!$T$38,1)="D"),"",IF(AND(ISNUMBER(J30),J30<ASOF),"⚠ เลยกำหนด",IF(AND(ISNUMBER(I30),I30<=ASOF+14,J30>=ASOF-7),"ช่วงนี้",""))) -> ช่วงนี้
A31: P9-001 | B31: แม่แบบ หลังคาลอนคู่, กันย้อน HV, Inverter < 200 kVA | C31: วศ.01 | D31: 01 | E31: 1.3.1 | F31: บันทึกส่งมอบพื้นที่ | G31: บันทึกส่งมอบพื้นที่ลงนาม กปภ.สาขา | H31: 0/100 | I31: ='P9-001'!$N$40 -> 46328 | J31: ='P9-001'!$O$40 -> 46328 | K31: =IF(OR(L31="Y",LEFT('P9-001'!$T$40,1)="D"),"",IF(AND(ISNUMBER(J31),J31<ASOF),"⚠ เลยกำหนด",IF(AND(ISNUMBER(I31),I31<=ASOF+14,J31>=ASOF-7),"ช่วงนี้",""))) -> ช่วงนี้
A32: P9-001 | B32: แม่แบบ หลังคาลอนคู่, กันย้อน HV, Inverter < 200 kVA | C32: วศ.01 | D32: 01 | E32: 1.3.2 | F32: สิ่งอำนวยความสะดวกหน้างาน (Mobilization) | G32: Site office / ไฟ-น้ำชั่วคราว / กองวัสดุ / ป้ายพร้อม + รูปถ่าย | H32: 0/100 | I32: ='P9-001'!$N$41 -> 46328 | J32: ='P9-001'!$O$41 -> 46328 | K32: =IF(OR(L32="Y",LEFT('P9-001'!$T$41,1)="D"),"",IF(AND(ISNUMBER(J32),J32<ASOF),"⚠ เลยกำหนด",IF(AND(ISNUMBER(I32),I32<=ASOF+14,J32>=ASOF-7),"ช่วงนี้",""))) -> ช่วงนี้
A33: P9-001 | B33: แม่แบบ หลังคาลอนคู่, กันย้อน HV, Inverter < 200 kVA | C33: วศ.01 | D33: 01 | E33: 1.3.3 | F33: คำขอปฏิบัติงาน R1 ฉบับแรก | G33: R1 ฉบับแรกอนุมัติโดย Inspector | H33: 0/100 | I33: ='P9-001'!$N$42 -> 46328 | J33: ='P9-001'!$O$42 -> 46328 | K33: =IF(OR(L33="Y",LEFT('P9-001'!$T$42,1)="D"),"",IF(AND(ISNUMBER(J33),J33<ASOF),"⚠ เลยกำหนด",IF(AND(ISNUMBER(I33),I33<=ASOF+14,J33>=ASOF-7),"ช่วงนี้",""))) -> ช่วงนี้
A34: P9-001 | B34: แม่แบบ หลังคาลอนคู่, กันย้อน HV, Inverter < 200 kVA | C34: วศ.01 | D34: 01 | E34: 1.4.1 | F34: ผลตรวจน้ำหนักบนหลังคา (เลือก อ.1 / แจ้ง) | G34: ผลคำนวณน้ำหนักบนหลังคา + เลือกขอ อ.1 หรือแจ้ง | H34: 0/100 | I34: ='P9-001'!$N$44 -> 46328 | J34: ='P9-001'!$O$44 -> 46328 | K34: =IF(OR(L34="Y",LEFT('P9-001'!$T$44,1)="D"),"",IF(AND(ISNUMBER(J34),J34<ASOF),"⚠ เลยกำหนด",IF(AND(ISNUMBER(I34),I34<=ASOF+14,J34>=ASOF-7),"ช่วงนี้",""))) -> ช่วงนี้
A35: P9-001 | B35: แม่แบบ หลังคาลอนคู่, กันย้อน HV, Inverter < 200 kVA | C35: วศ.01 | D35: 01 | E35: 1.4.2 | F35: ชุดเอกสารขออนุญาต / แจ้งเทศบาล | G35: ชุดเอกสารครบตามรายการของเทศบาล / อบต. | H35: 0/100 | I35: ='P9-001'!$N$45 -> 46328 | J35: ='P9-001'!$O$45 -> 46328 | K35: =IF(OR(L35="Y",LEFT('P9-001'!$T$45,1)="D"),"",IF(AND(ISNUMBER(J35),J35<ASOF),"⚠ เลยกำหนด",IF(AND(ISNUMBER(I35),I35<=ASOF+14,J35>=ASOF-7),"ช่วงนี้",""))) -> ช่วงนี้
A36: P9-001 | B36: แม่แบบ หลังคาลอนคู่, กันย้อน HV, Inverter < 200 kVA | C36: วศ.01 | D36: 01 | E36: 1.4.3 | F36: อ.1 / หนังสือรับแจ้งเทศบาล | G36: ใบรับคำขอ (ยื่น) → อ.1 / หนังสือรับแจ้ง (ได้รับ) | H36: 0/100 | I36: ='P9-001'!$N$46 -> 46328 | J36: ='P9-001'!$O$46 -> 46328 | K36: =IF(OR(L36="Y",LEFT('P9-001'!$T$46,1)="D"),"",IF(AND(ISNUMBER(J36),J36<ASOF),"⚠ เลยกำหนด",IF(AND(ISNUMBER(I36),I36<=ASOF+14,J36>=ASOF-7),"ช่วงนี้",""))) -> ช่วงนี้
A37: P9-001 | B37: แม่แบบ หลังคาลอนคู่, กันย้อน HV, Inverter < 200 kVA | C37: วศ.01 | D37: 01 | E37: 1.6.1 | F37: ผลตรวจเกณฑ์ยกเว้น กกพ. | G37: ผลตรวจเกณฑ์ยกเว้น + ช่องทางแจ้งที่เลือก | H37: 0/100 | I37: ='P9-001'!$N$53 | J37: ='P9-001'!$O$53 | K37: =IF(OR(L37="Y",LEFT('P9-001'!$T$53,1)="D"),"",IF(AND(ISNUMBER(J37),J37<ASOF),"⚠ เลยกำหนด",IF(AND(ISNUMBER(I37),I37<=ASOF+14,J37>=ASOF-7),"ช่วงนี้","")))
A38: P9-001 | B38: แม่แบบ หลังคาลอนคู่, กันย้อน HV, Inverter < 200 kVA | C38: วศ.01 | D38: 01 | E38: 1.6.2 | F38: หลักฐานแจ้งยกเว้น กกพ. | G38: หลักฐานการแจ้ง กกพ. / ชื่อบนเว็บ กกพ. | H38: 0/100 | I38: ='P9-001'!$N$54 | J38: ='P9-001'!$O$54 | K38: =IF(OR(L38="Y",LEFT('P9-001'!$T$54,1)="D"),"",IF(AND(ISNUMBER(J38),J38<ASOF),"⚠ เลยกำหนด",IF(AND(ISNUMBER(I38),I38<=ASOF+14,J38>=ASOF-7),"ช่วงนี้","")))
A39: P9-001 | B39: แม่แบบ หลังคาลอนคู่, กันย้อน HV, Inverter < 200 kVA | C39: วศ.01 | D39: 01 | E39: 2.1.1 | F39: ผังจุดยึด (Mark ตาม shop drawing) | G39: ผังจุดยึด / Mark ครบตาม shop drawing + รูปถ่าย | H39: =IF(COUNTIFS(SITE_ST,"P9-001",SITE_TYPE,"?*")>0,"ตามจุดติดตั้ง →","0/100") -> ตามจุดติดตั้ง → | I39: ='P9-001'!$N$63 -> 46328 | J39: ='P9-001'!$O$63 -> 46329 | K39: =IF(OR(L39="Y",LEFT('P9-001'!$T$63,1)="D"),"",IF(AND(ISNUMBER(J39),J39<ASOF),"⚠ เลยกำหนด",IF(AND(ISNUMBER(I39),I39<=ASOF+14,J39>=ASOF-7),"ช่วงนี้",""))) -> ช่วงนี้
A40: P9-001 | B40: แม่แบบ หลังคาลอนคู่, กันย้อน HV, Inverter < 200 kVA | C40: วศ.01 | D40: 01 | E40: 2.1.2 | F40: บันไดเซอร์วิส / ทางขึ้นลง + Lifeline ชั่วคราว | G40: บันไดตรวจรับแล้ว (ยึดผนังครบ, กรงต่อเนื่อง, ทาสีกันสนิม) ก่อนใช้ขึ้นลง | H40: 0/100 | I40: ='P9-001'!$N$64 -> 46328 | J40: ='P9-001'!$O$64 -> 46331 | K40: =IF(OR(L40="Y",LEFT('P9-001'!$T$64,1)="D"),"",IF(AND(ISNUMBER(J40),J40<ASOF),"⚠ เลยกำหนด",IF(AND(ISNUMBER(I40),I40<=ASOF+14,J40>=ASOF-7),"ช่วงนี้",""))) -> ช่วงนี้
...

Sheet Master Plan
A1: MASTER PLAN – โครงการ Solar Rooftop การประปาส่วนภูมิภาค เฟส 3–4
A2: 20 สถานี, สัญญา PEA(EMD)-03/2024 | D2: ✎ อัปเดตรายสัปดาห์ | J2: ⚙ สมมติฐาน | M2: ⚠ ความเสี่ยง | P2: ↻ บันทึกการเปลี่ยนแปลง | T2: ✗ Cost of Quality | W2: ◆ Milestone | Z2: ⟳ TCRoof (สด)
A3: วันที่ข้อมูล | C3: COD ทั้งเฟส (คาดการณ์) | D3: COD แล้ว | F3: ติดตั้งแล้ว | I3: กฟภ. ตรวจแล้ว | K3: ส่งมอบงวดแล้ว | N3: Milestone เสร็จ | P3: % งาน (ถ่วง kWp) | R3: สถานี COD ช้ากว่า Baseline | T3: ช้าแต่ยังไม่บันทึกเหตุผล
A4: =ASOF -> 46328 | C4: =MAX($AH$8:$AH$27) -> 46433 | D4: =COUNTIFS($X$8:$X$27,"<="&ASOF,$X$8:$X$27,"<>")&" / 20" -> 0 / 20 | F4: =COUNTIFS($N$8:$N$27,"<="&ASOF,$N$8:$N$27,"<>")&" / 20" -> 0 / 20 | I4: =COUNTIFS($O$8:$O$27,"<="&ASOF,$O$8:$O$27,"<>")&" / 20" -> 0 / 20 | K4: =COUNTIFS($Q$8:$Q$27,"<="&ASOF,$Q$8:$Q$27,"<>")&" / 20" -> 0 / 20 | N4: =TEXT(SUM($AK$8:$AK$27)/SUM($AL$8:$AL$27),"0%")&" ("&SUM($AK$8:$AK$27)&"/"&SUM($AL$8:$AL$27)&")" -> 0% (0/150) | P4: =SUMPRODUCT($AM$8:$AM$27,$F$8:$F$27)/SUM($F$8:$F$27) -> 0 | R4: =COUNTIF($AJ$8:$AJ$27,">0") -> 0 | T4: =COUNTIF($AP$8:$AP$27,">0") -> 0
A5: คลิกรหัสสถานีเพื่อเปิดแผนรายโครงการ, เขียว = ลิงก์จากชีต ‘อัปเดตรายสัปดาห์’, ฟ้า = แผนที่สูตรคำนวณ (เลื่อนเป็นวันทำงาน), Gantt: I ติดตั้ง, P กฟภ.ตรวจ, T IEC, H ส่งมอบ, G ยื่นขนานไฟ, S First Sync, ส้ม = สัปดาห์กำหนดรอบ, % งานสูงเพราะงานติดตั้งหนัก 90% ให้ดู Milestone คู่กัน
A6: สถานี | J6: ผู้รับผิดชอบ | N6: วันที่จริง / นัด (ลิงก์จาก ‘อัปเดตรายสัปดาห์’) | Y6: แผน (คำนวณ) | AI6: ผล | AT6: ตัวช่วย | BH6: =CHOOSE(MONTH(BH7),"ม.ค.","ก.พ.","มี.ค.","เม.ย.","พ.ค.","มิ.ย.","ก.ค.","ส.ค.","ก.ย.","ต.ค.","พ.ย.","ธ.ค.")&" "&RIGHT(YEAR(BH7)+543,2) -> ต.ค. 69 | BI6: =IF(MONTH(BI7)<>MONTH(BH7),CHOOSE(MONTH(BI7),"ม.ค.","ก.พ.","มี.ค.","เม.ย.","พ.ค.","มิ.ย.","ก.ค.","ส.ค.","ก.ย.","ต.ค.","พ.ย.","ธ.ค.")&" "&RIGHT(YEAR(BI7)+543,2),"") -> พ.ย. 69 | BJ6: =IF(MONTH(BJ7)<>MONTH(BI7),CHOOSE(MONTH(BJ7),"ม.ค.","ก.พ.","มี.ค.","เม.ย.","พ.ค.","มิ.ย.","ก.ค.","ส.ค.","ก.ย.","ต.ค.","พ.ย.","ธ.ค.")&" "&RIGHT(YEAR(BJ7)+543,2),"") | BK6: =IF(MONTH(BK7)<>MONTH(BJ7),CHOOSE(MONTH(BK7),"ม.ค.","ก.พ.","มี.ค.","เม.ย.","พ.ค.","มิ.ย.","ก.ค.","ส.ค.","ก.ย.","ต.ค.","พ.ย.","ธ.ค.")&" "&RIGHT(YEAR(BK7)+543,2),"") | BL6: =IF(MONTH(BL7)<>MONTH(BK7),CHOOSE(MONTH(BL7),"ม.ค.","ก.พ.","มี.ค.","เม.ย.","พ.ค.","มิ.ย.","ก.ค.","ส.ค.","ก.ย.","ต.ค.","พ.ย.","ธ.ค.")&" "&RIGHT(YEAR(BL7)+543,2),"") | BM6: =IF(MONTH(BM7)<>MONTH(BL7),CHOOSE(MONTH(BM7),"ม.ค.","ก.พ.","มี.ค.","เม.ย.","พ.ค.","มิ.ย.","ก.ค.","ส.ค.","ก.ย.","ต.ค.","พ.ย.","ธ.ค.")&" "&RIGHT(YEAR(BM7)+543,2),"") | BN6: =IF(MONTH(BN7)<>MONTH(BM7),CHOOSE(MONTH(BN7),"ม.ค.","ก.พ.","มี.ค.","เม.ย.","พ.ค.","มิ.ย.","ก.ค.","ส.ค.","ก.ย.","ต.ค.","พ.ย.","ธ.ค.")&" "&RIGHT(YEAR(BN7)+543,2),"") -> ธ.ค. 69 | BO6: =IF(MONTH(BO7)<>MONTH(BN7),CHOOSE(MONTH(BO7),"ม.ค.","ก.พ.","มี.ค.","เม.ย.","พ.ค.","มิ.ย.","ก.ค.","ส.ค.","ก.ย.","ต.ค.","พ.ย.","ธ.ค.")&" "&RIGHT(YEAR(BO7)+543,2),"") | BP6: =IF(MONTH(BP7)<>MONTH(BO7),CHOOSE(MONTH(BP7),"ม.ค.","ก.พ.","มี.ค.","เม.ย.","พ.ค.","มิ.ย.","ก.ค.","ส.ค.","ก.ย.","ต.ค.","พ.ย.","ธ.ค.")&" "&RIGHT(YEAR(BP7)+543,2),"") | ... DC6: =IF(MONTH(DC7)<>MONTH(DB7),CHOOSE(MONTH(DC7),"ม.ค.","ก.พ.","มี.ค.","เม.ย.","พ.ค.","มิ.ย.","ก.ค.","ส.ค.","ก.ย.","ต.ค.","พ.ย.","ธ.ค.")&" "&RIGHT(YEAR(DC7)+543,2),"")
A7: รหัส | B7: สถานี | C7: สาขา | D7: ภาค | E7: เขต กฟภ. | F7: kWp | G7: รอบ | H7: กำหนดรอบ | I7: COD Baseline | J7: วิศวกร | K7: Admin | L7: ผรม. | M7: พค.2 | N7: ติดตั้ง | O7: กฟภ.ตรวจ | P7: IEC 62446 | Q7: ส่งมอบงวด | R7: ยื่นขนานไฟ | S7: ยื่นแก้ไขล่าสุด | T7: กฟภ.อนุมัติ | U7: ชำระค่าธรรมเนียม | V7: ขอตรวจระบบ | W7: ยื่น พค.2 | X7: First Sync | Y7: ติดตั้ง | Z7: กฟภ.ตรวจ | AA7: IEC 62446 | AB7: ส่งมอบงวด | AC7: ยื่นขนานไฟ | AD7: กฟภ.อนุมัติ | AE7: ชำระค่าธรรมเนียม | AF7: ขอตรวจระบบ | AG7: ยื่น พค.2 | AH7: COD / First Sync | AI7: ส่งมอบงวดช้า (วัน) | AJ7: COD ช้ากว่า Baseline (วัน) | AK7: Milestone เสร็จ | AL7: จาก | AM7: % งาน | AN7: ⚠ ตรวจข้อมูล | AO7: เลื่อนที่อนุมัติ (วัน) | AP7: COD ช้าที่ยังไม่มีเหตุผล (วัน) | AQ7: งานแก้ซ้ำ (ครั้ง) | AR7: % MP ในแอป TCRoof | AS7: แก้ล่าสุดในแอป | AT7: คิวติดตั้ง (kWp สะสม) | AU7: ผรม. kWp/สัปดาห์ | AV7: วันตรวจเร็วสุด | AW7: คิว กฟภ. | AX7: กำลังตรวจเขต | AY7: คิววิศวกร | AZ7: วิศวกร ไซต์/สัปดาห์ | BA7: วัน IEC เร็วสุด | BB7: คิว IEC ผรม. | BC7: ผรม. IEC/สัปดาห์ | BD7: วันทำรายงาน | BE7: รอคิวเขต (วัน) | BF7: รอคิววิศวกร (วัน) | BH7: =GANTT_START -> 46321 | BI7: =BH7+7 -> 46328 | BJ7: =BI7+7 -> 46335 | BK7: =BJ7+7 -> 46342 | BL7: =BK7+7 -> 46349 | BM7: =BL7+7 -> 46356 | BN7: =BM7+7 -> 46363 | BO7: =BN7+7 -> 46370 | BP7: =BO7+7 -> 46377 | ... DC7: =DB7+7 -> 46650
A8: P9-001 | B8: แม่แบบ หลังคาลอนคู่, กันย้อน HV, Inverter < 200 kVA | C8: (ตัวอย่าง) | D8: ตัวอย่าง | E8: ตย.01 | F8: 150.48 | G8: รอบ 9 | H8: =PROJ_START+RD_SPAN -> 46403 | I8: =H8+33 -> 46436 | J8: วศ.01 | K8: Admin | L8: 01 | M8: N | N8: =IF(ISNUMBER(อัปเดตรายสัปดาห์!$AF8),อัปเดตรายสัปดาห์!$AF8,"") | O8: =IF(ISNUMBER(อัปเดตรายสัปดาห์!$AH8),อัปเดตรายสัปดาห์!$AH8,"") | P8: =IF(ISNUMBER(อัปเดตรายสัปดาห์!$AG8),อัปเดตรายสัปดาห์!$AG8,IF(AND(ISNUMBER(TCRoof!$AC$8),N(TCRoof!$AC$8)<=ASOF),TCRoof!$AC$8,"")) | Q8: =IF(ISNUMBER(อัปเดตรายสัปดาห์!$AL8),อัปเดตรายสัปดาห์!$AL8,"") | R8: =IF(ISNUMBER(อัปเดตรายสัปดาห์!$Q8),อัปเดตรายสัปดาห์!$Q8,"") | S8: =IF(ISNUMBER(อัปเดตรายสัปดาห์!$R8),อัปเดตรายสัปดาห์!$R8,"") | T8: =IF(ISNUMBER(อัปเดตรายสัปดาห์!$S8),อัปเดตรายสัปดาห์!$S8,IF(อัปเดตรายสัปดาห์!$S8="Y",ASOF,"")) | U8: =IF(ISNUMBER(อัปเดตรายสัปดาห์!$T8),อัปเดตรายสัปดาห์!$T8,IF(อัปเดตรายสัปดาห์!$T8="Y",ASOF,"")) | V8: =IF(ISNUMBER(อัปเดตรายสัปดาห์!$U8),อัปเดตรายสัปดาห์!$U8,IF(อัปเดตรายสัปดาห์!$U8="Y",ASOF,"")) | W8: =IF(ISNUMBER(อัปเดตรายสัปดาห์!$N8),อัปเดตรายสัปดาห์!$N8,"") | X8: =IF(ISNUMBER(อัปเดตรายสัปดาห์!$V8),อัปเดตรายสัปดาห์!$V8,IF(AND(ISNUMBER(TCRoof!$AD$8),N(TCRoof!$AD$8)<=ASOF),TCRoof!$AD$8,"")) | Y8: =IF(N8<>"",N8,WORKDAY((ASOF+LEAD_INST+7*INT((AT8-0.01)/MAX(1,AU8)))-1,1,HOLIDAYS)) -> 46349 | Z8: =IF(O8<>"",O8,WORKDAY((MAX(AV8+7*INT((AW8-1)/MAX(1,AX8)),AV8+7*INT((AY8-1)/MAX(1,AZ8))))-1,1,HOLIDAYS)) -> 46356 | AA8: =IF(P8<>"",P8,WORKDAY((BA8+7*INT((BB8-1)/MAX(1,BC8)))-1,1,HOLIDAYS)) -> 46359 | AB8: =IF(Q8<>"",Q8,WORKDAY((MAX(AA8+BD8,ASOF+1))-1,1,HOLIDAYS)) -> 46367 | AC8: =IF(R8<>"",R8,WORKDAY((MAX(Y8,ASOF)+LAG_GRID)-1,1,HOLIDAYS)) -> 46356 | AD8: =IF(T8<>"",T8,WORKDAY((MAX(WORKDAY(MAX(AC8,N(S8)),REVIEW_WD,HOLIDAYS),ASOF+1))-1,1,HOLIDAYS)) -> 46379 | AE8: =IF(U8<>"",U8,WORKDAY((MAX(AD8,ASOF)+FEE_DAYS)-1,1,HOLIDAYS)) -> 46386 | AF8: =IF(V8<>"",V8,WORKDAY((MAX(AA8,Z8,AE8,IF(AG8="",0,AG8+REVIEW_PK2),ASOF)+LAG_INSREQ)-1,1,HOLIDAYS)) -> 46391 | AG8: =IF(M8<>"Y","",IF(W8<>"",W8,WORKDAY((MAX(Y8,ASOF)+LAG_GRID)-1,1,HOLIDAYS))) | AH8: =IF(X8<>"",X8,WORKDAY(AF8,INSPECT_WD,HOLIDAYS)) -> 46433 | AI8: =IF(H8="","",AB8-H8) -> -36 | AJ8: =IF(I8="","",AH8-I8) -> -3 | AK8: =IF(AND(ISNUMBER(N8),N(N8)<=ASOF),1,0)+IF(AND(ISNUMBER(O8),N(O8)<=ASOF),1,0)+IF(AND(ISNUMBER(P8),N(P8)<=ASOF),1,0)+IF(AND(ISNUMBER(Q8),N(Q8)<=ASOF),1,0)+IF(AND(ISNUMBER(R8),N(R8)<=ASOF),1,0)+IF(AND(ISNUMBER(U8),N(U8)<=ASOF),1,0)+IF(AND(ISNUMBER(X8),N(X8)<=ASOF),1,0) -> 0 | AL8: 7 | AM8: ='P9-001'!$J$4 -> 0 | AN8: =TRIM(IF(AND(ISNUMBER(O8),NOT(ISNUMBER(N8))),"กฟภ.ตรวจก่อนติดตั้ง, ","")&IF(AND(ISNUMBER(P8),NOT(ISNUMBER(N8))),"IEC ก่อนติดตั้ง, ","")&IF(AND(ISNUMBER(Q8),NOT(ISNUMBER(N8))),"ส่งมอบก่อนติดตั้ง, ","")&IF(AND(ISNUMBER(Q8),ISNUMBER(P8),N(Q8)<N(P8)),"ส่งมอบก่อน IEC, ","")&IF(AND(ISNUMBER(อัปเดตรายสัปดาห์!$AG8),ISNUMBER(TCRoof!$AC$8),ABS(N(อัปเดตรายสัปดาห์!$AG8)-N(TCRoof!$AC$8))>3),"IEC Excel≠แอป, ","")&IF(AND(ISNUMBER(อัปเดตรายสัปดาห์!$V8),ISNUMBER(TCRoof!$AD$8),ABS(N(อัปเดตรายสัปดาห์!$V8)-N(TCRoof!$AD$8))>3),"COD Excel≠แอป, ","")&IF(AND(ISNUMBER(อัปเดตรายสัปดาห์!$AF8),ISNUMBER(TCRoof!$AB$8),ABS(N(อัปเดตรายสัปดาห์!$AF8)-N(TCRoof!$AB$8))>3),"ติดตั้ง Excel≠แอป, ","")&IF(AND(ISNUMBER(N8),N(N8)>ASOF,OR(WEEKDAY(N(N8),2)>5,COUNTIF(HOLIDAYS,N(N8))>0)),"นัดดับไฟตรงวันหยุด, ","")&IF(AND(ISNUMBER(O8),N(O8)>ASOF,OR(WEEKDAY(N(O8),2)>5,COUNTIF(HOLIDAYS,N(O8))>0)),"นัด กฟภ.ตรงวันหยุด, ","")&IF(AND(ISNUMBER(P8),N(P8)>ASOF,OR(WEEKDAY(N(P8),2)>5,COUNTIF(HOLIDAYS,N(P8))>0)),"นัด IECตรงวันหยุด, ","")&IF(AND(ISNUMBER(X8),N(X8)>ASOF,OR(WEEKDAY(N(X8),2)>5,COUNTIF(HOLIDAYS,N(X8))>0)),"นัด Syncตรงวันหยุด, ","")) | AO8: =SUMIFS(CR_COD,CR_ST,A8,CR_STAT,"อนุมัติ")+SUMIFS(CR_COD,CR_ST,"ทั้งเฟส",CR_STAT,"อนุมัติ")+SUMIFS(CR_COD,CR_ST,"ผรม. "&L8,CR_STAT,"อนุมัติ")+SUMIFS(CR_COD,CR_ST,"เขต "&E8,CR_STAT,"อนุมัติ") -> 0 | AP8: =IF(NOT(ISNUMBER(AJ8)),"",MAX(0,AJ8-AO8)) -> 0 | AQ8: =COUNTIF(RW_ST,A8) -> 0 | AR8: =IF(ISNUMBER(TCRoof!$I$8),TCRoof!$I$8,"") | AS8: =IF(ISNUMBER(TCRoof!$H$8),TCRoof!$H$8,"") | AT8: =IF(N8<>"","",SUMIFS($F$8:$F$27,$L$8:$L$27,L8,$N$8:$N$27,"",$H$8:$H$27,"<"&H8)+SUMIFS($F$8:$F$27,$L$8:$L$27,L8,$N$8:$N$27,"",$H$8:$H$27,H8,$A$8:$A$27,"<="&A8)+SUMIFS($F$8:$F$27,$L$8:$L$27,L8,$N$8:$N$27,">"&ASOF)) -> 150.48 | AU8: =IFERROR(VLOOKUP(L8,TEAM_TBL,2,0)*VLOOKUP(L8,TEAM_TBL,3,0),150) -> 150 | AV8: =IF(O8<>"","",MAX(Y8+LAG_PEA,ASOF+LAG_PEA)) -> 46356 | AW8: =IF(O8<>"","",COUNTIFS($E$8:$E$27,E8,$AV$8:$AV$27,"<"&AV8)+COUNTIFS($E$8:$E$27,E8,$AV$8:$AV$27,AV8,$A$8:$A$27,"<"&A8)+COUNTIFS($E$8:$E$27,E8,$O$8:$O$27,">"&ASOF)+1) -> 1 | AX8: =IFERROR(VLOOKUP(E8,ZONE_TBL,2,0),CAP_PEA) -> 3 | AY8: =IF(O8<>"","",COUNTIFS($J$8:$J$27,J8,$AV$8:$AV$27,"<"&AV8)+COUNTIFS($J$8:$J$27,J8,$AV$8:$AV$27,AV8,$A$8:$A$27,"<"&A8)+COUNTIFS($J$8:$J$27,J8,$O$8:$O$27,">"&ASOF)+1) -> 1 | AZ8: =IFERROR(VLOOKUP(J8,ENG_TBL,2,0),ENG_CAP) -> 3 | BA8: =IF(P8<>"","",MAX(Z8+LAG_IEC,ASOF+1)) -> 46359 | BB8: =IF(P8<>"","",COUNTIFS($L$8:$L$27,L8,$BA$8:$BA$27,"<"&BA8)+COUNTIFS($L$8:$L$27,L8,$BA$8:$BA$27,BA8,$A$8:$A$27,"<"&A8)+COUNTIFS($L$8:$L$27,L8,$P$8:$P$27,">"&ASOF)+1) -> 1 | BC8: =IFERROR(VLOOKUP(L8,TEAM_TBL,4,0)*VLOOKUP(L8,TEAM_TBL,5,0),3) -> 3 | BD8: =IFERROR(VLOOKUP(L8,TEAM_TBL,6,0),LAG_HO) -> 7 | BE8: =IF(ISNUMBER(AW8),7*INT((AW8-1)/MAX(1,AX8)),"") -> 0 | BF8: =IF(ISNUMBER(AY8),7*INT((AY8-1)/MAX(1,AZ8)),"") -> 0 | BH8: =IF(AND($Y8<>"",$Y8>=BH$7,$Y8<BH$7+7),"I","")&IF(AND($Z8<>"",$Z8>=BH$7,$Z8<BH$7+7),"P","")&IF(AND($AA8<>"",$AA8>=BH$7,$AA8<BH$7+7),"T","")&IF(AND($AB8<>"",$AB8>=BH$7,$AB8<BH$7+7),"H","")&IF(AND($AC8<>"",$AC8>=BH$7,$AC8<BH$7+7),"G","")&IF(AND($AH8<>"",$AH8>=BH$7,$AH8<BH$7+7),"S","") | BI8: =IF(AND($Y8<>"",$Y8>=BI$7,$Y8<BI$7+7),"I","")&IF(AND($Z8<>"",$Z8>=BI$7,$Z8<BI$7+7),"P","")&IF(AND($AA8<>"",$AA8>=BI$7,$AA8<BI$7+7),"T","")&IF(AND($AB8<>"",$AB8>=BI$7,$AB8<BI$7+7),"H","")&IF(AND($AC8<>"",$AC8>=BI$7,$AC8<BI$7+7),"G","")&IF(AND($AH8<>"",$AH8>=BI$7,$AH8<BI$7+7),"S","") | BJ8: =IF(AND($Y8<>"",$Y8>=BJ$7,$Y8<BJ$7+7),"I","")&IF(AND($Z8<>"",$Z8>=BJ$7,$Z8<BJ$7+7),"P","")&IF(AND($AA8<>"",$AA8>=BJ$7,$AA8<BJ$7+7),"T","")&IF(AND($AB8<>"",$AB8>=BJ$7,$AB8<BJ$7+7),"H","")&IF(AND($AC8<>"",$AC8>=BJ$7,$AC8<BJ$7+7),"G","")&IF(AND($AH8<>"",$AH8>=BJ$7,$AH8<BJ$7+7),"S","") | BK8: =IF(AND($Y8<>"",$Y8>=BK$7,$Y8<BK$7+7),"I","")&IF(AND($Z8<>"",$Z8>=BK$7,$Z8<BK$7+7),"P","")&IF(AND($AA8<>"",$AA8>=BK$7,$AA8<BK$7+7),"T","")&IF(AND($AB8<>"",$AB8>=BK$7,$AB8<BK$7+7),"H","")&IF(AND($AC8<>"",$AC8>=BK$7,$AC8<BK$7+7),"G","")&IF(AND($AH8<>"",$AH8>=BK$7,$AH8<BK$7+7),"S","") | BL8: =IF(AND($Y8<>"",$Y8>=BL$7,$Y8<BL$7+7),"I","")&IF(AND($Z8<>"",$Z8>=BL$7,$Z8<BL$7+7),"P","")&IF(AND($AA8<>"",$AA8>=BL$7,$AA8<BL$7+7),"T","")&IF(AND($AB8<>"",$AB8>=BL$7,$AB8<BL$7+7),"H","")&IF(AND($AC8<>"",$AC8>=BL$7,$AC8<BL$7+7),"G","")&IF(AND($AH8<>"",$AH8>=BL$7,$AH8<BL$7+7),"S","") -> I | BM8: =IF(AND($Y8<>"",$Y8>=BM$7,$Y8<BM$7+7),"I","")&IF(AND($Z8<>"",$Z8>=BM$7,$Z8<BM$7+7),"P","")&IF(AND($AA8<>"",$AA8>=BM$7,$AA8<BM$7+7),"T","")&IF(AND($AB8<>"",$AB8>=BM$7,$AB8<BM$7+7),"H","")&IF(AND($AC8<>"",$AC8>=BM$7,$AC8<BM$7+7),"G","")&IF(AND($AH8<>"",$AH8>=BM$7,$AH8<BM$7+7),"S","") -> PTG | BN8: =IF(AND($Y8<>"",$Y8>=BN$7,$Y8<BN$7+7),"I","")&IF(AND($Z8<>"",$Z8>=BN$7,$Z8<BN$7+7),"P","")&IF(AND($AA8<>"",$AA8>=BN$7,$AA8<BN$7+7),"T","")&IF(AND($AB8<>"",$AB8>=BN$7,$AB8<BN$7+7),"H","")&IF(AND($AC8<>"",$AC8>=BN$7,$AC8<BN$7+7),"G","")&IF(AND($AH8<>"",$AH8>=BN$7,$AH8<BN$7+7),"S","") -> H | BO8: =IF(AND($Y8<>"",$Y8>=BO$7,$Y8<BO$7+7),"I","")&IF(AND($Z8<>"",$Z8>=BO$7,$Z8<BO$7+7),"P","")&IF(AND($AA8<>"",$AA8>=BO$7,$AA8<BO$7+7),"T","")&IF(AND($AB8<>"",$AB8>=BO$7,$AB8<BO$7+7),"H","")&IF(AND($AC8<>"",$AC8>=BO$7,$AC8<BO$7+7),"G","")&IF(AND($AH8<>"",$AH8>=BO$7,$AH8<BO$7+7),"S","") | ... DC8: =IF(AND($Y8<>"",$Y8>=DC$7,$Y8<DC$7+7),"I","")&IF(AND($Z8<>"",$Z8>=DC$7,$Z8<DC$7+7),"P","")&IF(AND($AA8<>"",$AA8>=DC$7,$AA8<DC$7+7),"T","")&IF(AND($AB8<>"",$AB8>=DC$7,$AB8<DC$7+7),"H","")&IF(AND($AC8<>"",$AC8>=DC$7,$AC8<DC$7+7),"G","")&IF(AND($AH8<>"",$AH8>=DC$7,$AH8<DC$7+7),"S","")
A9: P9-002 | B9: แม่แบบ หลังคาลอนคู่, กันย้อน HV, Inverter ≥ 200 kVA | C9: (ตัวอย่าง) | D9: ตัวอย่าง | E9: ตย.02 | F9: 280.44 | G9: รอบ 9 | H9: =PROJ_START+RD_SPAN -> 46403 | I9: =H9+33 -> 46436 | J9: วศ.02 | K9: Admin | L9: 02 | M9: Y | N9: =IF(ISNUMBER(อัปเดตรายสัปดาห์!$AF9),อัปเดตรายสัปดาห์!$AF9,"") | O9: =IF(ISNUMBER(อัปเดตรายสัปดาห์!$AH9),อัปเดตรายสัปดาห์!$AH9,"") | P9: =IF(ISNUMBER(อัปเดตรายสัปดาห์!$AG9),อัปเดตรายสัปดาห์!$AG9,IF(AND(ISNUMBER(TCRoof!$AC$9),N(TCRoof!$AC$9)<=ASOF),TCRoof!$AC$9,"")) | Q9: =IF(ISNUMBER(อัปเดตรายสัปดาห์!$AL9),อัปเดตรายสัปดาห์!$AL9,"") | R9: =IF(ISNUMBER(อัปเดตรายสัปดาห์!$Q9),อัปเดตรายสัปดาห์!$Q9,"") | S9: =IF(ISNUMBER(อัปเดตรายสัปดาห์!$R9),อัปเดตรายสัปดาห์!$R9,"") | T9: =IF(ISNUMBER(อัปเดตรายสัปดาห์!$S9),อัปเดตรายสัปดาห์!$S9,IF(อัปเดตรายสัปดาห์!$S9="Y",ASOF,"")) | U9: =IF(ISNUMBER(อัปเดตรายสัปดาห์!$T9),อัปเดตรายสัปดาห์!$T9,IF(อัปเดตรายสัปดาห์!$T9="Y",ASOF,"")) | V9: =IF(ISNUMBER(อัปเดตรายสัปดาห์!$U9),อัปเดตรายสัปดาห์!$U9,IF(อัปเดตรายสัปดาห์!$U9="Y",ASOF,"")) | W9: =IF(ISNUMBER(อัปเดตรายสัปดาห์!$N9),อัปเดตรายสัปดาห์!$N9,"") | X9: =IF(ISNUMBER(อัปเดตรายสัปดาห์!$V9),อัปเดตรายสัปดาห์!$V9,IF(AND(ISNUMBER(TCRoof!$AD$9),N(TCRoof!$AD$9)<=ASOF),TCRoof!$AD$9,"")) | Y9: =IF(N9<>"",N9,WORKDAY((ASOF+LEAD_INST+7*INT((AT9-0.01)/MAX(1,AU9)))-1,1,HOLIDAYS)) -> 46349 | Z9: =IF(O9<>"",O9,WORKDAY((MAX(AV9+7*INT((AW9-1)/MAX(1,AX9)),AV9+7*INT((AY9-1)/MAX(1,AZ9))))-1,1,HOLIDAYS)) -> 46356 | AA9: =IF(P9<>"",P9,WORKDAY((BA9+7*INT((BB9-1)/MAX(1,BC9)))-1,1,HOLIDAYS)) -> 46359 | AB9: =IF(Q9<>"",Q9,WORKDAY((MAX(AA9+BD9,ASOF+1))-1,1,HOLIDAYS)) -> 46367 | AC9: =IF(R9<>"",R9,WORKDAY((MAX(Y9,ASOF)+LAG_GRID)-1,1,HOLIDAYS)) -> 46356 | AD9: =IF(T9<>"",T9,WORKDAY((MAX(WORKDAY(MAX(AC9,N(S9)),REVIEW_WD,HOLIDAYS),ASOF+1))-1,1,HOLIDAYS)) -> 46379 | AE9: =IF(U9<>"",U9,WORKDAY((MAX(AD9,ASOF)+FEE_DAYS)-1,1,HOLIDAYS)) -> 46386 | AF9: =IF(V9<>"",V9,WORKDAY((MAX(AA9,Z9,AE9,IF(AG9="",0,AG9+REVIEW_PK2),ASOF)+LAG_INSREQ)-1,1,HOLIDAYS)) -> 46391 | AG9: =IF(M9<>"Y","",IF(W9<>"",W9,WORKDAY((MAX(Y9,ASOF)+LAG_GRID)-1,1,HOLIDAYS))) -> 46356 | AH9: =IF(X9<>"",X9,WORKDAY(AF9,INSPECT_WD,HOLIDAYS)) -> 46433 | AI9: =IF(H9="","",AB9-H9) -> -36 | AJ9: =IF(I9="","",AH9-I9) -> -3 | AK9: =IF(AND(ISNUMBER(N9),N(N9)<=ASOF),1,0)+IF(AND(ISNUMBER(O9),N(O9)<=ASOF),1,0)+IF(AND(ISNUMBER(P9),N(P9)<=ASOF),1,0)+IF(AND(ISNUMBER(Q9),N(Q9)<=ASOF),1,0)+IF(AND(ISNUMBER(R9),N(R9)<=ASOF),1,0)+IF(AND(ISNUMBER(U9),N(U9)<=ASOF),1,0)+IF(AND(ISNUMBER(X9),N(X9)<=ASOF),1,0)+IF(AND(ISNUMBER(W9),N(W9)<=ASOF),1,0) -> 0 | AL9: 8 | AM9: ='P9-002'!$J$4 -> 0 | AN9: =TRIM(IF(AND(ISNUMBER(O9),NOT(ISNUMBER(N9))),"กฟภ.ตรวจก่อนติดตั้ง, ","")&IF(AND(ISNUMBER(P9),NOT(ISNUMBER(N9))),"IEC ก่อนติดตั้ง, ","")&IF(AND(ISNUMBER(Q9),NOT(ISNUMBER(N9))),"ส่งมอบก่อนติดตั้ง, ","")&IF(AND(ISNUMBER(Q9),ISNUMBER(P9),N(Q9)<N(P9)),"ส่งมอบก่อน IEC, ","")&IF(AND(ISNUMBER(อัปเดตรายสัปดาห์!$AG9),ISNUMBER(TCRoof!$AC$9),ABS(N(อัปเดตรายสัปดาห์!$AG9)-N(TCRoof!$AC$9))>3),"IEC Excel≠แอป, ","")&IF(AND(ISNUMBER(อัปเดตรายสัปดาห์!$V9),ISNUMBER(TCRoof!$AD$9),ABS(N(อัปเดตรายสัปดาห์!$V9)-N(TCRoof!$AD$9))>3),"COD Excel≠แอป, ","")&IF(AND(ISNUMBER(อัปเดตรายสัปดาห์!$AF9),ISNUMBER(TCRoof!$AB$9),ABS(N(อัปเดตรายสัปดาห์!$AF9)-N(TCRoof!$AB$9))>3),"ติดตั้ง Excel≠แอป, ","")&IF(AND(ISNUMBER(N9),N(N9)>ASOF,OR(WEEKDAY(N(N9),2)>5,COUNTIF(HOLIDAYS,N(N9))>0)),"นัดดับไฟตรงวันหยุด, ","")&IF(AND(ISNUMBER(O9),N(O9)>ASOF,OR(WEEKDAY(N(O9),2)>5,COUNTIF(HOLIDAYS,N(O9))>0)),"นัด กฟภ.ตรงวันหยุด, ","")&IF(AND(ISNUMBER(P9),N(P9)>ASOF,OR(WEEKDAY(N(P9),2)>5,COUNTIF(HOLIDAYS,N(P9))>0)),"นัด IECตรงวันหยุด, ","")&IF(AND(ISNUMBER(X9),N(X9)>ASOF,OR(WEEKDAY(N(X9),2)>5,COUNTIF(HOLIDAYS,N(X9))>0)),"นัด Syncตรงวันหยุด, ","")) | AO9: =SUMIFS(CR_COD,CR_ST,A9,CR_STAT,"อนุมัติ")+SUMIFS(CR_COD,CR_ST,"ทั้งเฟส",CR_STAT,"อนุมัติ")+SUMIFS(CR_COD,CR_ST,"ผรม. "&L9,CR_STAT,"อนุมัติ")+SUMIFS(CR_COD,CR_ST,"เขต "&E9,CR_STAT,"อนุมัติ") -> 0 | AP9: =IF(NOT(ISNUMBER(AJ9)),"",MAX(0,AJ9-AO9)) -> 0 | AQ9: =COUNTIF(RW_ST,A9) -> 0 | AR9: =IF(ISNUMBER(TCRoof!$I$9),TCRoof!$I$9,"") | AS9: =IF(ISNUMBER(TCRoof!$H$9),TCRoof!$H$9,"") | AT9: =IF(N9<>"","",SUMIFS($F$8:$F$27,$L$8:$L$27,L9,$N$8:$N$27,"",$H$8:$H$27,"<"&H9)+SUMIFS($F$8:$F$27,$L$8:$L$27,L9,$N$8:$N$27,"",$H$8:$H$27,H9,$A$8:$A$27,"<="&A9)+SUMIFS($F$8:$F$27,$L$8:$L$27,L9,$N$8:$N$27,">"&ASOF)) -> 280.44 | AU9: =IFERROR(VLOOKUP(L9,TEAM_TBL,2,0)*VLOOKUP(L9,TEAM_TBL,3,0),150) -> 150 | AV9: =IF(O9<>"","",MAX(Y9+LAG_PEA,ASOF+LAG_PEA)) -> 46356 | AW9: =IF(O9<>"","",COUNTIFS($E$8:$E$27,E9,$AV$8:$AV$27,"<"&AV9)+COUNTIFS($E$8:$E$27,E9,$AV$8:$AV$27,AV9,$A$8:$A$27,"<"&A9)+COUNTIFS($E$8:$E$27,E9,$O$8:$O$27,">"&ASOF)+1) -> 1 | AX9: =IFERROR(VLOOKUP(E9,ZONE_TBL,2,0),CAP_PEA) -> 3 | AY9: =IF(O9<>"","",COUNTIFS($J$8:$J$27,J9,$AV$8:$AV$27,"<"&AV9)+COUNTIFS($J$8:$J$27,J9,$AV$8:$AV$27,AV9,$A$8:$A$27,"<"&A9)+COUNTIFS($J$8:$J$27,J9,$O$8:$O$27,">"&ASOF)+1) -> 1 | AZ9: =IFERROR(VLOOKUP(J9,ENG_TBL,2,0),ENG_CAP) -> 3 | BA9: =IF(P9<>"","",MAX(Z9+LAG_IEC,ASOF+1)) -> 46359 | BB9: =IF(P9<>"","",COUNTIFS($L$8:$L$27,L9,$BA$8:$BA$27,"<"&BA9)+COUNTIFS($L$8:$L$27,L9,$BA$8:$BA$27,BA9,$A$8:$A$27,"<"&A9)+COUNTIFS($L$8:$L$27,L9,$P$8:$P$27,">"&ASOF)+1) -> 1 | BC9: =IFERROR(VLOOKUP(L9,TEAM_TBL,4,0)*VLOOKUP(L9,TEAM_TBL,5,0),3) -> 3 | BD9: =IFERROR(VLOOKUP(L9,TEAM_TBL,6,0),LAG_HO) -> 7 | BE9: =IF(ISNUMBER(AW9),7*INT((AW9-1)/MAX(1,AX9)),"") -> 0 | BF9: =IF(ISNUMBER(AY9),7*INT((AY9-1)/MAX(1,AZ9)),"") -> 0 | BH9: =IF(AND($Y9<>"",$Y9>=BH$7,$Y9<BH$7+7),"I","")&IF(AND($Z9<>"",$Z9>=BH$7,$Z9<BH$7+7),"P","")&IF(AND($AA9<>"",$AA9>=BH$7,$AA9<BH$7+7),"T","")&IF(AND($AB9<>"",$AB9>=BH$7,$AB9<BH$7+7),"H","")&IF(AND($AC9<>"",$AC9>=BH$7,$AC9<BH$7+7),"G","")&IF(AND($AH9<>"",$AH9>=BH$7,$AH9<BH$7+7),"S","") | BI9: =IF(AND($Y9<>"",$Y9>=BI$7,$Y9<BI$7+7),"I","")&IF(AND($Z9<>"",$Z9>=BI$7,$Z9<BI$7+7),"P","")&IF(AND($AA9<>"",$AA9>=BI$7,$AA9<BI$7+7),"T","")&IF(AND($AB9<>"",$AB9>=BI$7,$AB9<BI$7+7),"H","")&IF(AND($AC9<>"",$AC9>=BI$7,$AC9<BI$7+7),"G","")&IF(AND($AH9<>"",$AH9>=BI$7,$AH9<BI$7+7),"S","") | BJ9: =IF(AND($Y9<>"",$Y9>=BJ$7,$Y9<BJ$7+7),"I","")&IF(AND($Z9<>"",$Z9>=BJ$7,$Z9<BJ$7+7),"P","")&IF(AND($AA9<>"",$AA9>=BJ$7,$AA9<BJ$7+7),"T","")&IF(AND($AB9<>"",$AB9>=BJ$7,$AB9<BJ$7+7),"H","")&IF(AND($AC9<>"",$AC9>=BJ$7,$AC9<BJ$7+7),"G","")&IF(AND($AH9<>"",$AH9>=BJ$7,$AH9<BJ$7+7),"S","") | BK9: =IF(AND($Y9<>"",$Y9>=BK$7,$Y9<BK$7+7),"I","")&IF(AND($Z9<>"",$Z9>=BK$7,$Z9<BK$7+7),"P","")&IF(AND($AA9<>"",$AA9>=BK$7,$AA9<BK$7+7),"T","")&IF(AND($AB9<>"",$AB9>=BK$7,$AB9<BK$7+7),"H","")&IF(AND($AC9<>"",$AC9>=BK$7,$AC9<BK$7+7),"G","")&IF(AND($AH9<>"",$AH9>=BK$7,$AH9<BK$7+7),"S","") | BL9: =IF(AND($Y9<>"",$Y9>=BL$7,$Y9<BL$7+7),"I","")&IF(AND($Z9<>"",$Z9>=BL$7,$Z9<BL$7+7),"P","")&IF(AND($AA9<>"",$AA9>=BL$7,$AA9<BL$7+7),"T","")&IF(AND($AB9<>"",$AB9>=BL$7,$AB9<BL$7+7),"H","")&IF(AND($AC9<>"",$AC9>=BL$7,$AC9<BL$7+7),"G","")&IF(AND($AH9<>"",$AH9>=BL$7,$AH9<BL$7+7),"S","") -> I | BM9: =IF(AND($Y9<>"",$Y9>=BM$7,$Y9<BM$7+7),"I","")&IF(AND($Z9<>"",$Z9>=BM$7,$Z9<BM$7+7),"P","")&IF(AND($AA9<>"",$AA9>=BM$7,$AA9<BM$7+7),"T","")&IF(AND($AB9<>"",$AB9>=BM$7,$AB9<BM$7+7),"H","")&IF(AND($AC9<>"",$AC9>=BM$7,$AC9<BM$7+7),"G","")&IF(AND($AH9<>"",$AH9>=BM$7,$AH9<BM$7+7),"S","") -> PTG | BN9: =IF(AND($Y9<>"",$Y9>=BN$7,$Y9<BN$7+7),"I","")&IF(AND($Z9<>"",$Z9>=BN$7,$Z9<BN$7+7),"P","")&IF(AND($AA9<>"",$AA9>=BN$7,$AA9<BN$7+7),"T","")&IF(AND($AB9<>"",$AB9>=BN$7,$AB9<BN$7+7),"H","")&IF(AND($AC9<>"",$AC9>=BN$7,$AC9<BN$7+7),"G","")&IF(AND($AH9<>"",$AH9>=BN$7,$AH9<BN$7+7),"S","") -> H | BO9: =IF(AND($Y9<>"",$Y9>=BO$7,$Y9<BO$7+7),"I","")&IF(AND($Z9<>"",$Z9>=BO$7,$Z9<BO$7+7),"P","")&IF(AND($AA9<>"",$AA9>=BO$7,$AA9<BO$7+7),"T","")&IF(AND($AB9<>"",$AB9>=BO$7,$AB9<BO$7+7),"H","")&IF(AND($AC9<>"",$AC9>=BO$7,$AC9<BO$7+7),"G","")&IF(AND($AH9<>"",$AH9>=BO$7,$AH9<BO$7+7),"S","") | ... DC9: =IF(AND($Y9<>"",$Y9>=DC$7,$Y9<DC$7+7),"I","")&IF(AND($Z9<>"",$Z9>=DC$7,$Z9<DC$7+7),"P","")&IF(AND($AA9<>"",$AA9>=DC$7,$AA9<DC$7+7),"T","")&IF(AND($AB9<>"",$AB9>=DC$7,$AB9<DC$7+7),"H","")&IF(AND($AC9<>"",$AC9>=DC$7,$AC9<DC$7+7),"G","")&IF(AND($AH9<>"",$AH9>=DC$7,$AH9<DC$7+7),"S","")
A10: P9-003 | B10: แม่แบบ หลังคาลอนคู่, กันย้อน LV, Inverter < 200 kVA | C10: (ตัวอย่าง) | D10: ตัวอย่าง | E10: ตย.03 | F10: 150.48 | G10: รอบ 9 | H10: =PROJ_START+RD_SPAN -> 46403 | I10: =H10+33 -> 46436 | J10: วศ.03 | K10: Admin | L10: 03 | M10: N | N10: =IF(ISNUMBER(อัปเดตรายสัปดาห์!$AF10),อัปเดตรายสัปดาห์!$AF10,"") | O10: =IF(ISNUMBER(อัปเดตรายสัปดาห์!$AH10),อัปเดตรายสัปดาห์!$AH10,"") | P10: =IF(ISNUMBER(อัปเดตรายสัปดาห์!$AG10),อัปเดตรายสัปดาห์!$AG10,IF(AND(ISNUMBER(TCRoof!$AC$10),N(TCRoof!$AC$10)<=ASOF),TCRoof!$AC$10,"")) | Q10: =IF(ISNUMBER(อัปเดตรายสัปดาห์!$AL10),อัปเดตรายสัปดาห์!$AL10,"") | R10: =IF(ISNUMBER(อัปเดตรายสัปดาห์!$Q10),อัปเดตรายสัปดาห์!$Q10,"") | S10: =IF(ISNUMBER(อัปเดตรายสัปดาห์!$R10),อัปเดตรายสัปดาห์!$R10,"") | T10: =IF(ISNUMBER(อัปเดตรายสัปดาห์!$S10),อัปเดตรายสัปดาห์!$S10,IF(อัปเดตรายสัปดาห์!$S10="Y",ASOF,"")) | U10: =IF(ISNUMBER(อัปเดตรายสัปดาห์!$T10),อัปเดตรายสัปดาห์!$T10,IF(อัปเดตรายสัปดาห์!$T10="Y",ASOF,"")) | V10: =IF(ISNUMBER(อัปเดตรายสัปดาห์!$U10),อัปเดตรายสัปดาห์!$U10,IF(อัปเดตรายสัปดาห์!$U10="Y",ASOF,"")) | W10: =IF(ISNUMBER(อัปเดตรายสัปดาห์!$N10),อัปเดตรายสัปดาห์!$N10,"") | X10: =IF(ISNUMBER(อัปเดตรายสัปดาห์!$V10),อัปเดตรายสัปดาห์!$V10,IF(AND(ISNUMBER(TCRoof!$AD$10),N(TCRoof!$AD$10)<=ASOF),TCRoof!$AD$10,"")) | Y10: =IF(N10<>"",N10,WORKDAY((ASOF+LEAD_INST+7*INT((AT10-0.01)/MAX(1,AU10)))-1,1,HOLIDAYS)) -> 46349 | Z10: =IF(O10<>"",O10,WORKDAY((MAX(AV10+7*INT((AW10-1)/MAX(1,AX10)),AV10+7*INT((AY10-1)/MAX(1,AZ10))))-1,1,HOLIDAYS)) -> 46356 | AA10: =IF(P10<>"",P10,WORKDAY((BA10+7*INT((BB10-1)/MAX(1,BC10)))-1,1,HOLIDAYS)) -> 46359 | AB10: =IF(Q10<>"",Q10,WORKDAY((MAX(AA10+BD10,ASOF+1))-1,1,HOLIDAYS)) -> 46367 | AC10: =IF(R10<>"",R10,WORKDAY((MAX(Y10,ASOF)+LAG_GRID)-1,1,HOLIDAYS)) -> 46356 | AD10: =IF(T10<>"",T10,WORKDAY((MAX(WORKDAY(MAX(AC10,N(S10)),REVIEW_WD,HOLIDAYS),ASOF+1))-1,1,HOLIDAYS)) -> 46379 | AE10: =IF(U10<>"",U10,WORKDAY((MAX(AD10,ASOF)+FEE_DAYS)-1,1,HOLIDAYS)) -> 46386 | AF10: =IF(V10<>"",V10,WORKDAY((MAX(AA10,Z10,AE10,IF(AG10="",0,AG10+REVIEW_PK2),ASOF)+LAG_INSREQ)-1,1,HOLIDAYS)) -> 46391 | AG10: =IF(M10<>"Y","",IF(W10<>"",W10,WORKDAY((MAX(Y10,ASOF)+LAG_GRID)-1,1,HOLIDAYS))) | AH10: =IF(X10<>"",X10,WORKDAY(AF10,INSPECT_WD,HOLIDAYS)) -> 46433 | AI10: =IF(H10="","",AB10-H10) -> -36 | AJ10: =IF(I10="","",AH10-I10) -> -3 | AK10: =IF(AND(ISNUMBER(N10),N(N10)<=ASOF),1,0)+IF(AND(ISNUMBER(O10),N(O10)<=ASOF),1,0)+IF(AND(ISNUMBER(P10),N(P10)<=ASOF),1,0)+IF(AND(ISNUMBER(Q10),N(Q10)<=ASOF),1,0)+IF(AND(ISNUMBER(R10),N(R10)<=ASOF),1,0)+IF(AND(ISNUMBER(U10),N(U10)<=ASOF),1,0)+IF(AND(ISNUMBER(X10),N(X10)<=ASOF),1,0) -> 0 | AL10: 7 | AM10: ='P9-003'!$J$4 -> 0 | AN10: =TRIM(IF(AND(ISNUMBER(O10),NOT(ISNUMBER(N10))),"กฟภ.ตรวจก่อนติดตั้ง, ","")&IF(AND(ISNUMBER(P10),NOT(ISNUMBER(N10))),"IEC ก่อนติดตั้ง, ","")&IF(AND(ISNUMBER(Q10),NOT(ISNUMBER(N10))),"ส่งมอบก่อนติดตั้ง, ","")&IF(AND(ISNUMBER(Q10),ISNUMBER(P10),N(Q10)<N(P10)),"ส่งมอบก่อน IEC, ","")&IF(AND(ISNUMBER(อัปเดตรายสัปดาห์!$AG10),ISNUMBER(TCRoof!$AC$10),ABS(N(อัปเดตรายสัปดาห์!$AG10)-N(TCRoof!$AC$10))>3),"IEC Excel≠แอป, ","")&IF(AND(ISNUMBER(อัปเดตรายสัปดาห์!$V10),ISNUMBER(TCRoof!$AD$10),ABS(N(อัปเดตรายสัปดาห์!$V10)-N(TCRoof!$AD$10))>3),"COD Excel≠แอป, ","")&IF(AND(ISNUMBER(อัปเดตรายสัปดาห์!$AF10),ISNUMBER(TCRoof!$AB$10),ABS(N(อัปเดตรายสัปดาห์!$AF10)-N(TCRoof!$AB$10))>3),"ติดตั้ง Excel≠แอป, ","")&IF(AND(ISNUMBER(N10),N(N10)>ASOF,OR(WEEKDAY(N(N10),2)>5,COUNTIF(HOLIDAYS,N(N10))>0)),"นัดดับไฟตรงวันหยุด, ","")&IF(AND(ISNUMBER(O10),N(O10)>ASOF,OR(WEEKDAY(N(O10),2)>5,COUNTIF(HOLIDAYS,N(O10))>0)),"นัด กฟภ.ตรงวันหยุด, ","")&IF(AND(ISNUMBER(P10),N(P10)>ASOF,OR(WEEKDAY(N(P10),2)>5,COUNTIF(HOLIDAYS,N(P10))>0)),"นัด IECตรงวันหยุด, ","")&IF(AND(ISNUMBER(X10),N(X10)>ASOF,OR(WEEKDAY(N(X10),2)>5,COUNTIF(HOLIDAYS,N(X10))>0)),"นัด Syncตรงวันหยุด, ","")) | AO10: =SUMIFS(CR_COD,CR_ST,A10,CR_STAT,"อนุมัติ")+SUMIFS(CR_COD,CR_ST,"ทั้งเฟส",CR_STAT,"อนุมัติ")+SUMIFS(CR_COD,CR_ST,"ผรม. "&L10,CR_STAT,"อนุมัติ")+SUMIFS(CR_COD,CR_ST,"เขต "&E10,CR_STAT,"อนุมัติ") -> 0 | AP10: =IF(NOT(ISNUMBER(AJ10)),"",MAX(0,AJ10-AO10)) -> 0 | AQ10: =COUNTIF(RW_ST,A10) -> 0 | AR10: =IF(ISNUMBER(TCRoof!$I$10),TCRoof!$I$10,"") | AS10: =IF(ISNUMBER(TCRoof!$H$10),TCRoof!$H$10,"") | AT10: =IF(N10<>"","",SUMIFS($F$8:$F$27,$L$8:$L$27,L10,$N$8:$N$27,"",$H$8:$H$27,"<"&H10)+SUMIFS($F$8:$F$27,$L$8:$L$27,L10,$N$8:$N$27,"",$H$8:$H$27,H10,$A$8:$A$27,"<="&A10)+SUMIFS($F$8:$F$27,$L$8:$L$27,L10,$N$8:$N$27,">"&ASOF)) -> 150.48 | AU10: =IFERROR(VLOOKUP(L10,TEAM_TBL,2,0)*VLOOKUP(L10,TEAM_TBL,3,0),150) -> 150 | AV10: =IF(O10<>"","",MAX(Y10+LAG_PEA,ASOF+LAG_PEA)) -> 46356 | AW10: =IF(O10<>"","",COUNTIFS($E$8:$E$27,E10,$AV$8:$AV$27,"<"&AV10)+COUNTIFS($E$8:$E$27,E10,$AV$8:$AV$27,AV10,$A$8:$A$27,"<"&A10)+COUNTIFS($E$8:$E$27,E10,$O$8:$O$27,">"&ASOF)+1) -> 1 | AX10: =IFERROR(VLOOKUP(E10,ZONE_TBL,2,0),CAP_PEA) -> 3 | AY10: =IF(O10<>"","",COUNTIFS($J$8:$J$27,J10,$AV$8:$AV$27,"<"&AV10)+COUNTIFS($J$8:$J$27,J10,$AV$8:$AV$27,AV10,$A$8:$A$27,"<"&A10)+COUNTIFS($J$8:$J$27,J10,$O$8:$O$27,">"&ASOF)+1) -> 1 | AZ10: =IFERROR(VLOOKUP(J10,ENG_TBL,2,0),ENG_CAP) -> 3 | BA10: =IF(P10<>"","",MAX(Z10+LAG_IEC,ASOF+1)) -> 46359 | BB10: =IF(P10<>"","",COUNTIFS($L$8:$L$27,L10,$BA$8:$BA$27,"<"&BA10)+COUNTIFS($L$8:$L$27,L10,$BA$8:$BA$27,BA10,$A$8:$A$27,"<"&A10)+COUNTIFS($L$8:$L$27,L10,$P$8:$P$27,">"&ASOF)+1) -> 1 | BC10: =IFERROR(VLOOKUP(L10,TEAM_TBL,4,0)*VLOOKUP(L10,TEAM_TBL,5,0),3) -> 3 | BD10: =IFERROR(VLOOKUP(L10,TEAM_TBL,6,0),LAG_HO) -> 7 | BE10: =IF(ISNUMBER(AW10),7*INT((AW10-1)/MAX(1,AX10)),"") -> 0 | BF10: =IF(ISNUMBER(AY10),7*INT((AY10-1)/MAX(1,AZ10)),"") -> 0 | BH10: =IF(AND($Y10<>"",$Y10>=BH$7,$Y10<BH$7+7),"I","")&IF(AND($Z10<>"",$Z10>=BH$7,$Z10<BH$7+7),"P","")&IF(AND($AA10<>"",$AA10>=BH$7,$AA10<BH$7+7),"T","")&IF(AND($AB10<>"",$AB10>=BH$7,$AB10<BH$7+7),"H","")&IF(AND($AC10<>"",$AC10>=BH$7,$AC10<BH$7+7),"G","")&IF(AND($AH10<>"",$AH10>=BH$7,$AH10<BH$7+7),"S","") | BI10: =IF(AND($Y10<>"",$Y10>=BI$7,$Y10<BI$7+7),"I","")&IF(AND($Z10<>"",$Z10>=BI$7,$Z10<BI$7+7),"P","")&IF(AND($AA10<>"",$AA10>=BI$7,$AA10<BI$7+7),"T","")&IF(AND($AB10<>"",$AB10>=BI$7,$AB10<BI$7+7),"H","")&IF(AND($AC10<>"",$AC10>=BI$7,$AC10<BI$7+7),"G","")&IF(AND($AH10<>"",$AH10>=BI$7,$AH10<BI$7+7),"S","") | BJ10: =IF(AND($Y10<>"",$Y10>=BJ$7,$Y10<BJ$7+7),"I","")&IF(AND($Z10<>"",$Z10>=BJ$7,$Z10<BJ$7+7),"P","")&IF(AND($AA10<>"",$AA10>=BJ$7,$AA10<BJ$7+7),"T","")&IF(AND($AB10<>"",$AB10>=BJ$7,$AB10<BJ$7+7),"H","")&IF(AND($AC10<>"",$AC10>=BJ$7,$AC10<BJ$7+7),"G","")&IF(AND($AH10<>"",$AH10>=BJ$7,$AH10<BJ$7+7),"S","") | BK10: =IF(AND($Y10<>"",$Y10>=BK$7,$Y10<BK$7+7),"I","")&IF(AND($Z10<>"",$Z10>=BK$7,$Z10<BK$7+7),"P","")&IF(AND($AA10<>"",$AA10>=BK$7,$AA10<BK$7+7),"T","")&IF(AND($AB10<>"",$AB10>=BK$7,$AB10<BK$7+7),"H","")&IF(AND($AC10<>"",$AC10>=BK$7,$AC10<BK$7+7),"G","")&IF(AND($AH10<>"",$AH10>=BK$7,$AH10<BK$7+7),"S","") | BL10: =IF(AND($Y10<>"",$Y10>=BL$7,$Y10<BL$7+7),"I","")&IF(AND($Z10<>"",$Z10>=BL$7,$Z10<BL$7+7),"P","")&IF(AND($AA10<>"",$AA10>=BL$7,$AA10<BL$7+7),"T","")&IF(AND($AB10<>"",$AB10>=BL$7,$AB10<BL$7+7),"H","")&IF(AND($AC10<>"",$AC10>=BL$7,$AC10<BL$7+7),"G","")&IF(AND($AH10<>"",$AH10>=BL$7,$AH10<BL$7+7),"S","") -> I | BM10: =IF(AND($Y10<>"",$Y10>=BM$7,$Y10<BM$7+7),"I","")&IF(AND($Z10<>"",$Z10>=BM$7,$Z10<BM$7+7),"P","")&IF(AND($AA10<>"",$AA10>=BM$7,$AA10<BM$7+7),"T","")&IF(AND($AB10<>"",$AB10>=BM$7,$AB10<BM$7+7),"H","")&IF(AND($AC10<>"",$AC10>=BM$7,$AC10<BM$7+7),"G","")&IF(AND($AH10<>"",$AH10>=BM$7,$AH10<BM$7+7),"S","") -> PTG | BN10: =IF(AND($Y10<>"",$Y10>=BN$7,$Y10<BN$7+7),"I","")&IF(AND($Z10<>"",$Z10>=BN$7,$Z10<BN$7+7),"P","")&IF(AND($AA10<>"",$AA10>=BN$7,$AA10<BN$7+7),"T","")&IF(AND($AB10<>"",$AB10>=BN$7,$AB10<BN$7+7),"H","")&IF(AND($AC10<>"",$AC10>=BN$7,$AC10<BN$7+7),"G","")&IF(AND($AH10<>"",$AH10>=BN$7,$AH10<BN$7+7),"S","") -> H | BO10: =IF(AND($Y10<>"",$Y10>=BO$7,$Y10<BO$7+7),"I","")&IF(AND($Z10<>"",$Z10>=BO$7,$Z10<BO$7+7),"P","")&IF(AND($AA10<>"",$AA10>=BO$7,$AA10<BO$7+7),"T","")&IF(AND($AB10<>"",$AB10>=BO$7,$AB10<BO$7+7),"H","")&IF(AND($AC10<>"",$AC10>=BO$7,$AC10<BO$7+7),"G","")&IF(AND($AH10<>"",$AH10>=BO$7,$AH10<BO$7+7),"S","") | ... DC10: =IF(AND($Y10<>"",$Y10>=DC$7,$Y10<DC$7+7),"I","")&IF(AND($Z10<>"",$Z10>=DC$7,$Z10<DC$7+7),"P","")&IF(AND($AA10<>"",$AA10>=DC$7,$AA10<DC$7+7),"T","")&IF(AND($AB10<>"",$AB10>=DC$7,$AB10<DC$7+7),"H","")&IF(AND($AC10<>"",$AC10>=DC$7,$AC10<DC$7+7),"G","")&IF(AND($AH10<>"",$AH10>=DC$7,$AH10<DC$7+7),"S","")
